Workbook

Sheet 시트
A1: 이름 | B1: 임관년도 | C1: MBTI | D1: 이메일 | E1: 유형 | F1: 적성분야설명 | G1: 야전·실무형(R) | H1: 기술·분석형(I) | I1: 창의형(A) | J1: 관계형(S) | K1: 리더형(E) | L1: 행정·관리형(C) | M1: Merged Doc ID - 장교 진로 접합도 검사(72문항) | N1: Merged Doc URL - 장교 진로 접합도 검사(72문항) | O1: Link to merged Doc - 장교 진로 접합도 검사(72문항) | P1: Document Merge Status - 장교 진로 접합도 검사(72문항) | Q1: Merged Doc ID - 장교 진로 적합도 검사(72문항) | R1: Merged Doc URL - 장교 진로 적합도 검사(72문항) | S1: Link to merged Doc - 장교 진로 적합도 검사(72문항) | T1: Document Merge Status - 장교 진로 적합도 검사(72문항) | U1: Merged Doc ID - 장교 진로적합도 검사(72문항) | V1: Merged Doc URL - 장교 진로적합도 검사(72문항) | W1: Link to merged Doc - 장교 진로적합도 검사(72문항) | X1: Document Merge Status - 장교 진로적합도 검사(72문항) | Y1: Merged Doc ID - 장교 진로 적합도 검사(72문항_) | Z1: Merged Doc URL - 장교 진로 적합도 검사(72문항_) | AA1: Link to merged Doc - 장교 진로 적합도 검사(72문항_) | AB1: Document Merge Status - 장교 진로 적합도 검사(72문항_) | AC1: 스크립트_처리상태 | AD1: 스크립트_처리시각 | AE1: 스크립트_PDF_FILE_ID | AF1: 스크립트_PDF_URL | AG1: 스크립트_오류내용 | AH1: 스크립트_시도횟수 | AI1: 스크립트_Brevo_Message_ID
A2: {='설문시트'!C2:C610} -> 최종혁 | B2: {='설문시트'!D2:D610} -> 2025 | C2: {='설문시트'!E2:E610} -> Intp | D2: {='설문시트'!F2:F610} -> jonghyeokchoi77@gmail.com | E2: {=IF(LEN(G2:G610), BYROW(G2:L610, LAMBDA(row, INDEX(G1:L1, MATCH(MAX(row), row, 0)))), "")} -> #VALUE! | F2: {=IF(E2:E610="", , IFERROR(VLOOKUP(E2:E610, '분석자료'!$A1:$B7, 2, FALSE),""))} -> #VALUE! | G2: {=IF('설문시트'!G2:G610="", "", ('설문시트'!G2:G610)+('설문시트'!M2:M610)+('설문시트'!S2:S610)+('설문시트'!Y2:Y610)+('설문시트'!AE2:AE610)+('설문시트'!AK2:AK610)+('설문시트'!AQ2:AQ610)+('설문시트'!AW2:AW610)+('설문시트'!BC2:BC610)+('설문시트'!BI2:BI610)+('설문시트'!BO2:BO610)+('설문시트'!BU2:BU610))} -> 60 | H2: {=IF('설문시트'!H2:H610="", "", ('설문시트'!H2:H610)+('설문시트'!N2:N610)+('설문시트'!T2:T610)+('설문시트'!Z2:Z610)+('설문시트'!AF2:AF610)+('설문시트'!AL2:AL610)+('설문시트'!AR2:AR610)+('설문시트'!AX2:AX610)+('설문시트'!BD2:BD610)+('설문시트'!BJ2:BJ610)+('설문시트'!BP2:BP610)+('설문시트'!BV2:BV610))} -> 60 | I2: {=IF('설문시트'!I2:I610="", "", ('설문시트'!I2:I610)+('설문시트'!O2:O610)+('설문시트'!U2:U610)+('설문시트'!AA2:AA610)+('설문시트'!AG2:AG610)+('설문시트'!AM2:AM610)+('설문시트'!AS2:AS610)+('설문시트'!AY2:AY610)+('설문시트'!BE2:BE610)+('설문시트'!BK2:BK610)+('설문시트'!BQ2:BQ610)+('설문시트'!BW2:BW610))} -> #VALUE! | J2: {=IF('설문시트'!J2:J610="", "", ('설문시트'!J2:J610)+('설문시트'!P2:P610)+('설문시트'!V2:V610)+('설문시트'!AB2:AB610)+('설문시트'!AH2:AH610)+('설문시트'!AN2:AN610)+('설문시트'!AT2:AT610)+('설문시트'!AZ2:AZ610)+('설문시트'!BF2:BF610)+('설문시트'!BL2:BL610)+('설문시트'!BR2:BR610)+('설문시트'!BX2:BX610))} -> 60 | K2: {=IF('설문시트'!K2:K610="", "", ('설문시트'!K2:K610)+('설문시트'!Q2:Q610)+('설문시트'!W2:W610)+('설문시트'!AC2:AC610)+('설문시트'!AI2:AI610)+('설문시트'!AO2:AO610)+('설문시트'!AU2:AU610)+('설문시트'!BA2:BA610)+('설문시트'!BG2:BG610)+('설문시트'!BM2:BM610)+('설문시트'!BS2:BS610)+('설문시트'!BY2:BY610))} -> 60 | L2: {=IF('설문시트'!L2:L610="", "", ('설문시트'!L2:L610)+('설문시트'!R2:R610)+('설문시트'!X2:X610)+('설문시트'!AD2:AD610)+('설문시트'!AJ2:AJ610)+('설문시트'!AP2:AP610)+('설문시트'!AV2:AV610)+('설문시트'!BB2:BB610)+('설문시트'!BH2:BH610)+('설문시트'!BN2:BN610)+('설문시트'!BT2:BT610)+('설문시트'!BZ2:BZ610))} -> 60 | U2: 1IV1pwtmfvm5MlG7dlYwDbre6pHeS7PjI | V2: https://drive.google.com/file/d/1IV1pwtmfvm5MlG7dlYwDbre6pHeS7PjI/view?usp=drivesdk | W2: =HYPERLINK("https://drive.google.com/file/d/1IV1pwtmfvm5MlG7dlYwDbre6pHeS7PjI/view?usp=drivesdk","최종혁_진로적성검사_2026") -> 최종혁_진로적성검사_2026 | X2: Document successfully created; Document successfully merged; PDF created; Manually run by jeongjinung4@gmail.com; Timestamp: Aug 13, 2026 12:03 AM | AA2: SENT | AB2: 46247.569 | AC2: 재발송오류 | AG2: 수식 결과가 준비되지 않았습니다. 행: 2
A3: 너ㅓㅁ | B3: 2020 | C3: HHIK | D3: jonghyeokchoi77@gmail.com | E3: 야전·실무형(R) | F3: 귀하의 진로적성검사 결과를 종합하면 야전·실무형(R) 성향이 두드러지며, 이는 장비 운용과 현장 중심의 임무 수행에서 강점을 보이는 전형적인 야전형 장교로 성장할 가능성을 의미합니다. 이러한 성향은 군 환경에서 전투장비 운용과 유지관리, 전술적 운용, 병력 통제 등 실제 전투력과 직결되는 분야에서 특히 중요한 역할을 하며, 전투장비를 운용하는 보병(기보)·포병·기갑·방공·육군항공과 같은 전투임무 위주 병과뿐 아니라 공병, 정보통신,화학 등 기술 기반 병과에서도 높은 적합성을 보입니다. 전투병과 특기 선택시는 작전, 군수, 획득분야가 가장 적합합니다. 또한 군수, 병기, 병참, 수송 분야에서도 장비 관리와 운용 능력을 효과적으로 발휘할 수 있습니다. 전문인력 분야로는 통신·공병 등 기술 전문 분야나 무기체계 획득 및 관리와 같은 획득 전문 영역, 장비 중심 연구개발 분야에서도 발전 가능성이 큽니다. 현실형 장교는 전투 및 훈련 상황에서 빠르고 정확한 판단과 실행력을 바탕으로 가시적인 성과를 창출하며, 부하들에게 신뢰를 주는 장점이 있습니다. 다만 단기적 실행에 집중하는 경향으로 인해 장기적 안목 형성과 체계적인 기획 능력, 세밀한 의사소통, 유연한 상황 대응 및 병사 개개인에 대한 심리적 관리 측면에서는 보완이 필요합니다. 따라서 리더형(E, 리더십)이나 행정관리형(C, 정확한 업무수행) 성향을 함께 강화한다면 더욱 높은 성과를 기대할 수 있습니다. | G3: 35 | H3: 34 | I3: 31 | J3: 34 | K3: 30 | L3: 34 | U3: 1-0RO3NrgxfxyRJeHSN-4akdrCnVx0OeA | V3: https://drive.google.com/file/d/1-0RO3NrgxfxyRJeHSN-4akdrCnVx0OeA/view?usp=drivesdk | W3: =HYPERLINK("https://drive.google.com/file/d/1-0RO3NrgxfxyRJeHSN-4akdrCnVx0OeA/view?usp=drivesdk","너ㅓㅁ_진로적성검사_2026") -> 너ㅓㅁ_진로적성검사_2026 | X3: Document successfully created; Document successfully merged; PDF created; Manually run by jeongjinung4@gmail.com; Timestamp: Aug 13, 2026 12:50 AM | AA3: SENT | AB3: 46247.586
A4: 김민석 | B4: 2023 | C4: ESTP | D4: sdijk2114@naver.com | E4: 리더형(E) | F4: 귀하의 검사 결과, 리더형(E) 성향이 강하게 나타났습니다. 리더십과 의사결정 능력(협의, 조정)이 뛰어나며, 조직을 이끌고 목표를 달성하는 데 강점을 가진 유형입니다. 또한 이 유형은 상황을 빠르게 파악하고 방향을 설정하여 조직을 이끄는 능력이 뛰어나며, 부하들을 동기부여하고 목표 달성을 위해 자원을 효과적으로 배분하는 데 능숙합니다. 군에서는 이러한 성향이 지휘관 역할과 직결됩니다. 귀하에게는 보병, 포병, 기갑 등 모든 전투 병과에서의 전투부대 지휘 역할에 적합하여 조직 관리 능력을 발휘할 수 있습니다. 전문인력 분야에서는 정책전문, 국제전문(무관 등), 획득전문(방위사업 관련) 분야가 적합합니다. 향후에는 단순한 리더십을 넘어 전문성과 현장 이해를 함께 갖추는 것이 중요합니다. 야전·실무형(R,현장감각)이나 관계형(S,대인관계) 성향을 보완한다면 더욱 균형 잡힌 지휘관으로 성장할 수 있습니다. 또한 전투병과 장교는 지휘관과 참모직위를 모두 이수해야 하므로 참모로서의 섬세함과 업무관리 능력을 함양해야 한다. | G4: 29 | H4: 28 | I4: 22 | J4: 38 | K4: 43 | L4: 34 | U4: 1KdBrPVfN8pl2bRjryvrYxC0AF6PKQC7L | V4: https://drive.google.com/file/d/1KdBrPVfN8pl2bRjryvrYxC0AF6PKQC7L/view?usp=drivesdk | W4: =HYPERLINK("https://drive.google.com/file/d/1KdBrPVfN8pl2bRjryvrYxC0AF6PKQC7L/view?usp=drivesdk","김민석_진로적성검사_2026") -> 김민석_진로적성검사_2026 | X4: Document successfully created; Document successfully merged; PDF created; Manually run by jeongjinung4@gmail.com; Timestamp: Aug 13, 2026 1:02 AM | AA4: SENT | AB4: 46247.586
A5: Jejsj | B5: 2020 | C5: Ahah | D5: jonghyeokchoi77@gmail.com | E5: 창의형(A) | F5: 귀하의 진로적성검사 결과, 창의형(A) 성향이 높게 나타났습니다. 창의적인 표현과 방법, 새로운 아이디어를 통해 조직에 활력을 불어넣는 역할을 합니다. 군 조직에서는 이러한 성향이 장병 사기진작, 홍보, 심리전, 문화 활동 등에서 중요한 의미를 갖습니다. 귀하에게는 전투병과 인사특기,정훈병과가 적합하며, 인사근무 및 사기진작 활동, 영상 제작 및 콘텐츠 기획을 통한 군 홍보활동 등의 분야에서 강점을 발휘할 수 있습니다. 또한 인사행정이나 군사경찰 기능 중 일부 분야에서도 창의적 역할을 수행할 수 있습니다. 전문인력 분야에서는 정책전문(국방정책 홍보) 또는 국방홍보원 등의 미디어 분야로의 확장이 가능합니다. 군 조직 특성상 기본적인 규율과 체계 적응이 중요하므로, 행정관리형(C, 규율중시, 정확성)이나 관계형(S, 협업관계) 역량을 함께 보완한다면 보다 안정적인 성과를 낼 수 있습니다. 위에서 추천드린 전투병과(인사특기), 군사경찰 병과 역시 지휘관 직위를 필수로 이수해야 하므로 야전부대 현장 감각을 유지하고 의사소통 및 대인관계 형성과 같은 리더십을 함양에도 힘써야 합니다. | G5: 35 | H5: 35 | I5: 36 | J5: 34 | K5: 32 | L5: 29 | U5: 1W-oWx_3ctKLtW9gVxNH-oyNmgjvhqUrT | V5: https://drive.google.com/file/d/1W-oWx_3ctKLtW9gVxNH-oyNmgjvhqUrT/view?usp=drivesdk | W5: =HYPERLINK("https://drive.google.com/file/d/1W-oWx_3ctKLtW9gVxNH-oyNmgjvhqUrT/view?usp=drivesdk","Jejsj_진로적성검사_2026") -> Jejsj_진로적성검사_2026 | X5: Document successfully created; Document successfully merged; PDF created; Manually run by jeongjinung4@gmail.com; Timestamp: Aug 13, 2026 1:02 AM | AA5: SENT | AB5: 46247.586
A6: 80 황우진 | B6: 2025 | C6: ENFJ | D6: a52154309@gmail.com | E6: 야전·실무형(R) | F6: 귀하의 진로적성검사 결과를 종합하면 야전·실무형(R) 성향이 두드러지며, 이는 장비 운용과 현장 중심의 임무 수행에서 강점을 보이는 전형적인 야전형 장교로 성장할 가능성을 의미합니다. 이러한 성향은 군 환경에서 전투장비 운용과 유지관리, 전술적 운용, 병력 통제 등 실제 전투력과 직결되는 분야에서 특히 중요한 역할을 하며, 전투장비를 운용하는 보병(기보)·포병·기갑·방공·육군항공과 같은 전투임무 위주 병과뿐 아니라 공병, 정보통신,화학 등 기술 기반 병과에서도 높은 적합성을 보입니다. 전투병과 특기 선택시는 작전, 군수, 획득분야가 가장 적합합니다. 또한 군수, 병기, 병참, 수송 분야에서도 장비 관리와 운용 능력을 효과적으로 발휘할 수 있습니다. 전문인력 분야로는 통신·공병 등 기술 전문 분야나 무기체계 획득 및 관리와 같은 획득 전문 영역, 장비 중심 연구개발 분야에서도 발전 가능성이 큽니다. 현실형 장교는 전투 및 훈련 상황에서 빠르고 정확한 판단과 실행력을 바탕으로 가시적인 성과를 창출하며, 부하들에게 신뢰를 주는 장점이 있습니다. 다만 단기적 실행에 집중하는 경향으로 인해 장기적 안목 형성과 체계적인 기획 능력, 세밀한 의사소통, 유연한 상황 대응 및 병사 개개인에 대한 심리적 관리 측면에서는 보완이 필요합니다. 따라서 리더형(E, 리더십)이나 행정관리형(C, 정확한 업무수행) 성향을 함께 강화한다면 더욱 높은 성과를 기대할 수 있습니다. | G6: 32 | H6: 21 | I6: 26 | J6: 28 | K6: 29 | L6: 22 | U6: 144wcmvlQy_ITIep6ift_l2hfNl8ySgrB | V6: https://drive.google.com/file/d/144wcmvlQy_ITIep6ift_l2hfNl8ySgrB/view?usp=drivesdk | W6: =HYPERLINK("https://drive.google.com/file/d/144wcmvlQy_ITIep6ift_l2hfNl8ySgrB/view?usp=drivesdk","80 황우진_진로적성검사_2026") -> 80 황우진_진로적성검사_2026 | X6: Document successfully created; Document successfully merged; PDF created; Manually run by jeongjinung4@gmail.com; Timestamp: Aug 13, 2026 1:02 AM | AA6: SENT | AB6: 46247.586
A7: Bdhdh | B7: 2020 | C7: Jaja | D7: jonghyeokchoi77@gmail.com | E7: 기술·분석형(I) | F7: 귀하의 검사 결과, 기술·분석형(I) 성향이 중심적으로 나타났습니다. 분석적 사고와 문제 해결 능력이 뛰어나며, 복잡한 시스템과 정보를 이해하고 활용하는 데 강점을 지닌 유형입니다. 군에서는 이러한 능력이 정보전, 기술전, 미래전 수행에 핵심적으로 활용됩니다. 귀하에게는 정보, 정보통신, 화학 병과 등이 특히 적합하며, 기술적 분석이 요구되는 공병 및 항공 분야에서도 역량을 발휘할 수 있습니다. 전문인력 분야에서는 사이버, 연구개발, 국방분석 등 특수전문 영역이 적합하며, 정책전문이나 국제전문 분야에서도 분석 기반 의사결정 능력을 활용할 수 있습니다. 향후에는 기술적 이해뿐 아니라 야전에서 실제 적용 능력을 함께 강화하는 것이 중요합니다. 야전·실무형(R, 현장감각)이나 행정관리형(C, 체계적 업무수행) 성향을 보완한다면 실무와 분석을 겸비한 핵심 인재로 성장할 수 있습니다. 그러나 현상 분석에 집중하는 경향으로 인해 의사결정이 지연되거나 실행력이 부족해질 수 있음을 유의해야 합니다. 위에서 추천드린 병과 역시 지휘관 직위를 필수로 이수해야 하므로 야전부대 현장 감각을 유지하고 의사소통 및 대인관계 형성과 같은 리더십을 함양에도 힘써야 합니다. | G7: 30 | H7: 35 | I7: 33 | J7: 33 | K7: 35 | L7: 32 | U7: 1u36TW0H2J4_dtDzllqptBT8fuTzYkwhY | V7: https://drive.google.com/file/d/1u36TW0H2J4_dtDzllqptBT8fuTzYkwhY/view?usp=drivesdk | W7: =HYPERLINK("https://drive.google.com/file/d/1u36TW0H2J4_dtDzllqptBT8fuTzYkwhY/view?usp=drivesdk","Bdhdh_진로적성검사_2026") -> Bdhdh_진로적성검사_2026 | X7: Document successfully created; Document successfully merged; PDF created; Run via form trigger as jeongjinung4@gmail.com; Timestamp: Aug 13, 2026 1:21 AM | AA7: SENT | AB7: 46247.599
A8: Shej | B8: 2020 | C8: Shhs | D8: jonghyeokchoi77@gmail.com | E8: 관계형(S) | F8: 귀하의 검사 결과, 관계형(S) 성향이 중심적으로 나타났습니다. 사람을 이해하고 돕는 데 강점을 가진 유형으로, 조직 내 안정과 협력을 이끄는 중요한 역할을 수행합니다. 귀하에게는 전투병과(인사특기, 작전특기), 인사행정, 정훈, 군의, 의정, 간호 분야가 적합하여, 대인관계 중심 역할에서 역량을 발휘할 수 있습니다. 전문인력 분야에서는 정책전문(교육, 복지 및 인사 정책), 국제전문(협력 및 교류), 교육·교수 중심의 특수전문 분야가 적합합니다. 향후에는 조직 운영 능력을 강화하는 것이 중요합니다. 야전·실무형(R, 병력 및 장비운용)과 리더형(E,리더십) 성향을 함께 발전시키면 지휘 및 관리 역할에서도 큰 강점을 발휘할 수 있습니다. 위에서 추천드린 전투병과(인사특기, 작전특기)는 지휘관 직위를 필수로 이수해야 하므로 야전부대 현장 감각을 유지하며 리더십 함양에도 힘써야 합니다. | G8: 38 | H8: 31 | I8: 36 | J8: 39 | K8: 31 | L8: 38 | U8: 1vo1rB6vwCKjIy1t2I8ljlSMwn-q2P6cv | V8: https://drive.google.com/file/d/1vo1rB6vwCKjIy1t2I8ljlSMwn-q2P6cv/view?usp=drivesdk | W8: =HYPERLINK("https://drive.google.com/file/d/1vo1rB6vwCKjIy1t2I8ljlSMwn-q2P6cv/view?usp=drivesdk","Shej_진로적성검사_2026") -> Shej_진로적성검사_2026 | X8: Document successfully created; Document successfully merged; PDF created; Run via form trigger as jeongjinung4@gmail.com; Timestamp: Aug 13, 2026 1:26 AM | AA8: SENT | AB8: 46247.604
A9: Llll | B9: 2020 | C9: Jaja | D9: jonghyeokchoi77@gmail.com | E9: 창의형(A) | F9: 귀하의 진로적성검사 결과, 창의형(A) 성향이 높게 나타났습니다. 창의적인 표현과 방법, 새로운 아이디어를 통해 조직에 활력을 불어넣는 역할을 합니다. 군 조직에서는 이러한 성향이 장병 사기진작, 홍보, 심리전, 문화 활동 등에서 중요한 의미를 갖습니다. 귀하에게는 전투병과 인사특기,정훈병과가 적합하며, 인사근무 및 사기진작 활동, 영상 제작 및 콘텐츠 기획을 통한 군 홍보활동 등의 분야에서 강점을 발휘할 수 있습니다. 또한 인사행정이나 군사경찰 기능 중 일부 분야에서도 창의적 역할을 수행할 수 있습니다. 전문인력 분야에서는 정책전문(국방정책 홍보) 또는 국방홍보원 등의 미디어 분야로의 확장이 가능합니다. 군 조직 특성상 기본적인 규율과 체계 적응이 중요하므로, 행정관리형(C, 규율중시, 정확성)이나 관계형(S, 협업관계) 역량을 함께 보완한다면 보다 안정적인 성과를 낼 수 있습니다. 위에서 추천드린 전투병과(인사특기), 군사경찰 병과 역시 지휘관 직위를 필수로 이수해야 하므로 야전부대 현장 감각을 유지하고 의사소통 및 대인관계 형성과 같은 리더십을 함양에도 힘써야 합니다. | G9: 28 | H9: 32 | I9: 33 | J9: 33 | K9: 29 | L9: 30 | U9: 1_kdhskxzCes-CLYCtHw-cueVjOPugmez | V9: https://drive.google.com/file/d/1_kdhskxzCes-CLYCtHw-cueVjOPugmez/view?usp=drivesdk | W9: =HYPERLINK("https://drive.google.com/file/d/1_kdhskxzCes-CLYCtHw-cueVjOPugmez/view?usp=drivesdk","Llll_진로적성검사_2026") -> Llll_진로적성검사_2026 | X9: Document successfully created; Document successfully merged; PDF created; Run via form trigger as jeongjinung4@gmail.com; Timestamp: Aug 13, 2026 1:29 AM | AA9: SENT | AB9: 46247.604
A10: 테스트 | B10: 1 | C10: 1 | D10: enrud1103@naver.com | E10: 야전·실무형(R) | F10: 귀하의 진로적성검사 결과를 종합하면 야전·실무형(R) 성향이 두드러지며, 이는 장비 운용과 현장 중심의 임무 수행에서 강점을 보이는 전형적인 야전형 장교로 성장할 가능성을 의미합니다. 이러한 성향은 군 환경에서 전투장비 운용과 유지관리, 전술적 운용, 병력 통제 등 실제 전투력과 직결되는 분야에서 특히 중요한 역할을 하며, 전투장비를 운용하는 보병(기보)·포병·기갑·방공·육군항공과 같은 전투임무 위주 병과뿐 아니라 공병, 정보통신,화학 등 기술 기반 병과에서도 높은 적합성을 보입니다. 전투병과 특기 선택시는 작전, 군수, 획득분야가 가장 적합합니다. 또한 군수, 병기, 병참, 수송 분야에서도 장비 관리와 운용 능력을 효과적으로 발휘할 수 있습니다. 전문인력 분야로는 통신·공병 등 기술 전문 분야나 무기체계 획득 및 관리와 같은 획득 전문 영역, 장비 중심 연구개발 분야에서도 발전 가능성이 큽니다. 현실형 장교는 전투 및 훈련 상황에서 빠르고 정확한 판단과 실행력을 바탕으로 가시적인 성과를 창출하며, 부하들에게 신뢰를 주는 장점이 있습니다. 다만 단기적 실행에 집중하는 경향으로 인해 장기적 안목 형성과 체계적인 기획 능력, 세밀한 의사소통, 유연한 상황 대응 및 병사 개개인에 대한 심리적 관리 측면에서는 보완이 필요합니다. 따라서 리더형(E, 리더십)이나 행정관리형(C, 정확한 업무수행) 성향을 함께 강화한다면 더욱 높은 성과를 기대할 수 있습니다. | G10: 60 | H10: 60 | I10: 60 | J10: 60 | K10: 60 | L10: 60 | U10: 1uIc2jVTPADxfQL9QOXXBCov_l9G5Tl53 | V10: https://drive.google.com/file/d/1uIc2jVTPADxfQL9QOXXBCov_l9G5Tl53/view?usp=drivesdk | W10: =HYPERLINK("https://drive.google.com/file/d/1uIc2jVTPADxfQL9QOXXBCov_l9G5Tl53/view?usp=drivesdk","테스트_진로적성검사_2026") -> 테스트_진로적성검사_2026 | X10: Document successfully created; Document successfully merged; PDF created; Run via form trigger as jeongjinung4@gmail.com; Timestamp: Aug 13, 2026 1:45 AM | AA10: SENT | AB10: 46247.618
A11: 이상준 | B11: 2026 | C11: ESFJ | D11: william0724@naver.com | E11: 창의형(A) | F11: 귀하의 진로적성검사 결과, 창의형(A) 성향이 높게 나타났습니다. 창의적인 표현과 방법, 새로운 아이디어를 통해 조직에 활력을 불어넣는 역할을 합니다. 군 조직에서는 이러한 성향이 장병 사기진작, 홍보, 심리전, 문화 활동 등에서 중요한 의미를 갖습니다. 귀하에게는 전투병과 인사특기,정훈병과가 적합하며, 인사근무 및 사기진작 활동, 영상 제작 및 콘텐츠 기획을 통한 군 홍보활동 등의 분야에서 강점을 발휘할 수 있습니다. 또한 인사행정이나 군사경찰 기능 중 일부 분야에서도 창의적 역할을 수행할 수 있습니다. 전문인력 분야에서는 정책전문(국방정책 홍보) 또는 국방홍보원 등의 미디어 분야로의 확장이 가능합니다. 군 조직 특성상 기본적인 규율과 체계 적응이 중요하므로, 행정관리형(C, 규율중시, 정확성)이나 관계형(S, 협업관계) 역량을 함께 보완한다면 보다 안정적인 성과를 낼 수 있습니다. 위에서 추천드린 전투병과(인사특기), 군사경찰 병과 역시 지휘관 직위를 필수로 이수해야 하므로 야전부대 현장 감각을 유지하고 의사소통 및 대인관계 형성과 같은 리더십을 함양에도 힘써야 합니다. | G11: 47 | H11: 59 | I11: 60 | J11: 60 | K11: 60 | L11: 60 | U11: 1noC7m_W_Tcqiihiaxr4EWdEm8wtp0AKt | V11: https://drive.google.com/file/d/1noC7m_W_Tcqiihiaxr4EWdEm8wtp0AKt/view?usp=drivesdk | W11: =HYPERLINK("https://drive.google.com/file/d/1noC7m_W_Tcqiihiaxr4EWdEm8wtp0AKt/view?usp=drivesdk","이상준_진로적성검사_2026") -> 이상준_진로적성검사_2026 | X11: Document successfully created; Document successfully merged; PDF created; Run via form trigger as jeongjinung4@gmail.com; Timestamp: Aug 13, 2026 1:50 AM | AA11: SENT | AB11: 46247.619
A12: 강재우 | B12: 2026 | C12: ISFP | D12: kjw020219@gmail.com | E12: 관계형(S) | F12: 귀하의 검사 결과, 관계형(S) 성향이 중심적으로 나타났습니다. 사람을 이해하고 돕는 데 강점을 가진 유형으로, 조직 내 안정과 협력을 이끄는 중요한 역할을 수행합니다. 귀하에게는 전투병과(인사특기, 작전특기), 인사행정, 정훈, 군의, 의정, 간호 분야가 적합하여, 대인관계 중심 역할에서 역량을 발휘할 수 있습니다. 전문인력 분야에서는 정책전문(교육, 복지 및 인사 정책), 국제전문(협력 및 교류), 교육·교수 중심의 특수전문 분야가 적합합니다. 향후에는 조직 운영 능력을 강화하는 것이 중요합니다. 야전·실무형(R, 병력 및 장비운용)과 리더형(E,리더십) 성향을 함께 발전시키면 지휘 및 관리 역할에서도 큰 강점을 발휘할 수 있습니다. 위에서 추천드린 전투병과(인사특기, 작전특기)는 지휘관 직위를 필수로 이수해야 하므로 야전부대 현장 감각을 유지하며 리더십 함양에도 힘써야 합니다. | G12: 28 | H12: 14 | I12: 17 | J12: 54 | K12: 47 | L12: 46 | U12: 1tihl1yNwF6prmqhhJp2geT-D4cvfCTMH | V12: https://drive.google.com/file/d/1tihl1yNwF6prmqhhJp2geT-D4cvfCTMH/view?usp=drivesdk | W12: =HYPERLINK("https://drive.google.com/file/d/1tihl1yNwF6prmqhhJp2geT-D4cvfCTMH/view?usp=drivesdk","강재우_진로적성검사_2026") -> 강재우_진로적성검사_2026 | X12: Document successfully created; Document successfully merged; PDF created; Run via form trigger as jeongjinung4@gmail.com; Timestamp: Aug 13, 2026 1:51 AM | AA12: SENT | AB12: 46247.636
A13: 이재완 | B13: 2006 | C13: INTJ | D13: sdh220216@sdh.hs.kr | E13: 야전·실무형(R) | F13: 귀하의 진로적성검사 결과를 종합하면 야전·실무형(R) 성향이 두드러지며, 이는 장비 운용과 현장 중심의 임무 수행에서 강점을 보이는 전형적인 야전형 장교로 성장할 가능성을 의미합니다. 이러한 성향은 군 환경에서 전투장비 운용과 유지관리, 전술적 운용, 병력 통제 등 실제 전투력과 직결되는 분야에서 특히 중요한 역할을 하며, 전투장비를 운용하는 보병(기보)·포병·기갑·방공·육군항공과 같은 전투임무 위주 병과뿐 아니라 공병, 정보통신,화학 등 기술 기반 병과에서도 높은 적합성을 보입니다. 전투병과 특기 선택시는 작전, 군수, 획득분야가 가장 적합합니다. 또한 군수, 병기, 병참, 수송 분야에서도 장비 관리와 운용 능력을 효과적으로 발휘할 수 있습니다. 전문인력 분야로는 통신·공병 등 기술 전문 분야나 무기체계 획득 및 관리와 같은 획득 전문 영역, 장비 중심 연구개발 분야에서도 발전 가능성이 큽니다. 현실형 장교는 전투 및 훈련 상황에서 빠르고 정확한 판단과 실행력을 바탕으로 가시적인 성과를 창출하며, 부하들에게 신뢰를 주는 장점이 있습니다. 다만 단기적 실행에 집중하는 경향으로 인해 장기적 안목 형성과 체계적인 기획 능력, 세밀한 의사소통, 유연한 상황 대응 및 병사 개개인에 대한 심리적 관리 측면에서는 보완이 필요합니다. 따라서 리더형(E, 리더십)이나 행정관리형(C, 정확한 업무수행) 성향을 함께 강화한다면 더욱 높은 성과를 기대할 수 있습니다. | G13: 12 | H13: 12 | I13: 12 | J13: 12 | K13: 12 | L13: 12 | U13: 14NKD0cZHbATNwnFwiavMZEv6hIn4w7H6 | V13: https://drive.google.com/file/d/14NKD0cZHbATNwnFwiavMZEv6hIn4w7H6/view?usp=drivesdk | W13: =HYPERLINK("https://drive.google.com/file/d/14NKD0cZHbATNwnFwiavMZEv6hIn4w7H6/view?usp=drivesdk","이재완_진로적성검사_2026") -> 이재완_진로적성검사_2026 | X13: Document successfully created; Document successfully merged; PDF created; Run via form trigger as jeongjinung4@gmail.com; Timestamp: Aug 13, 2026 2:16 AM | AA13: SENT | AB13: 46247.637
A14: 최종혁 | B14: 2025 | C14: Intp | D14: jonghyeokchoi@gmail.com | E14: 기술·분석형(I) | F14: 귀하의 검사 결과, 기술·분석형(I) 성향이 중심적으로 나타났습니다. 분석적 사고와 문제 해결 능력이 뛰어나며, 복잡한 시스템과 정보를 이해하고 활용하는 데 강점을 지닌 유형입니다. 군에서는 이러한 능력이 정보전, 기술전, 미래전 수행에 핵심적으로 활용됩니다. 귀하에게는 정보, 정보통신, 화학 병과 등이 특히 적합하며, 기술적 분석이 요구되는 공병 및 항공 분야에서도 역량을 발휘할 수 있습니다. 전문인력 분야에서는 사이버, 연구개발, 국방분석 등 특수전문 영역이 적합하며, 정책전문이나 국제전문 분야에서도 분석 기반 의사결정 능력을 활용할 수 있습니다. 향후에는 기술적 이해뿐 아니라 야전에서 실제 적용 능력을 함께 강화하는 것이 중요합니다. 야전·실무형(R, 현장감각)이나 행정관리형(C, 체계적 업무수행) 성향을 보완한다면 실무와 분석을 겸비한 핵심 인재로 성장할 수 있습니다. 그러나 현상 분석에 집중하는 경향으로 인해 의사결정이 지연되거나 실행력이 부족해질 수 있음을 유의해야 합니다. 위에서 추천드린 병과 역시 지휘관 직위를 필수로 이수해야 하므로 야전부대 현장 감각을 유지하고 의사소통 및 대인관계 형성과 같은 리더십을 함양에도 힘써야 합니다. | G14: 34 | H14: 37 | I14: 36 | J14: 32 | K14: 37 | L14: 37 | U14: 13tK4fO9NOyBeRqkwrzv2gBrZWlpBHgZo | V14: https://drive.google.com/file/d/13tK4fO9NOyBeRqkwrzv2gBrZWlpBHgZo/view?usp=drivesdk | W14: =HYPERLINK("https://drive.google.com/file/d/13tK4fO9NOyBeRqkwrzv2gBrZWlpBHgZo/view?usp=drivesdk","최종혁_진로적성검사_2026") -> 최종혁_진로적성검사_2026 | X14: Document successfully created; Document successfully merged; PDF created; Run via form trigger as jeongjinung4@gmail.com; Timestamp: Aug 13, 2026 2:18 AM | AA14: SENT | AB14: 46247.638 | AC14: 재발송완료 | AD14: 46272.384 | AE14: 1pQ4IrmYM9grvLxeoPGFH2RfySIteJSup | AF14: https://drive.google.com/file/d/1pQ4IrmYM9grvLxeoPGFH2RfySIteJSup/view?usp=drivesdk | AI14: <202609070012.14497679086@smtp-relay.mailin.fr>
A15: 유성혁 | B15: 2025 | C15: ESTJ | D15: kimnummun@gmail.com | E15: 관계형(S) | F15: 귀하의 검사 결과, 관계형(S) 성향이 중심적으로 나타났습니다. 사람을 이해하고 돕는 데 강점을 가진 유형으로, 조직 내 안정과 협력을 이끄는 중요한 역할을 수행합니다. 귀하에게는 전투병과(인사특기, 작전특기), 인사행정, 정훈, 군의, 의정, 간호 분야가 적합하여, 대인관계 중심 역할에서 역량을 발휘할 수 있습니다. 전문인력 분야에서는 정책전문(교육, 복지 및 인사 정책), 국제전문(협력 및 교류), 교육·교수 중심의 특수전문 분야가 적합합니다. 향후에는 조직 운영 능력을 강화하는 것이 중요합니다. 야전·실무형(R, 병력 및 장비운용)과 리더형(E,리더십) 성향을 함께 발전시키면 지휘 및 관리 역할에서도 큰 강점을 발휘할 수 있습니다. 위에서 추천드린 전투병과(인사특기, 작전특기)는 지휘관 직위를 필수로 이수해야 하므로 야전부대 현장 감각을 유지하며 리더십 함양에도 힘써야 합니다. | G15: 44 | H15: 49 | I15: 39 | J15: 58 | K15: 55 | L15: 57 | U15: 1zjuWJq9vmOdzqJZevIsiaLd8NCLTkDsg | V15: https://drive.google.com/file/d/1zjuWJq9vmOdzqJZevIsiaLd8NCLTkDsg/view?usp=drivesdk | W15: =HYPERLINK("https://drive.google.com/file/d/1zjuWJq9vmOdzqJZevIsiaLd8NCLTkDsg/view?usp=drivesdk","유성혁_진로적성검사_2026") -> 유성혁_진로적성검사_2026 | X15: Document successfully created; Document successfully merged; PDF created; Run via form trigger as jeongjinung4@gmail.com; Timestamp: Aug 13, 2026 2:19 AM | AA15: SENT | AB15: 46247.64
A16: 전태은 | B16: 2025 | C16: ESFP | D16: jte0506@naver.com | E16: 관계형(S) | F16: 귀하의 검사 결과, 관계형(S) 성향이 중심적으로 나타났습니다. 사람을 이해하고 돕는 데 강점을 가진 유형으로, 조직 내 안정과 협력을 이끄는 중요한 역할을 수행합니다. 귀하에게는 전투병과(인사특기, 작전특기), 인사행정, 정훈, 군의, 의정, 간호 분야가 적합하여, 대인관계 중심 역할에서 역량을 발휘할 수 있습니다. 전문인력 분야에서는 정책전문(교육, 복지 및 인사 정책), 국제전문(협력 및 교류), 교육·교수 중심의 특수전문 분야가 적합합니다. 향후에는 조직 운영 능력을 강화하는 것이 중요합니다. 야전·실무형(R, 병력 및 장비운용)과 리더형(E,리더십) 성향을 함께 발전시키면 지휘 및 관리 역할에서도 큰 강점을 발휘할 수 있습니다. 위에서 추천드린 전투병과(인사특기, 작전특기)는 지휘관 직위를 필수로 이수해야 하므로 야전부대 현장 감각을 유지하며 리더십 함양에도 힘써야 합니다. | G16: 37 | H16: 36 | I16: 37 | J16: 45 | K16: 39 | L16: 41 | U16: 108P3955RebOzhC8_t9VyJxCdebxUlNOR | V16: https://drive.google.com/file/d/108P3955RebOzhC8_t9VyJxCdebxUlNOR/view?usp=drivesdk | W16: =HYPERLINK("https://drive.google.com/file/d/108P3955RebOzhC8_t9VyJxCdebxUlNOR/view?usp=drivesdk","전태은_진로적성검사_2026") -> 전태은_진로적성검사_2026 | X16: Document successfully created; Document successfully merged; PDF created; Run via form trigger as jeongjinung4@gmail.com; Timestamp: Aug 13, 2026 2:21 AM | AA16: SENT | AB16: 46247.64
A17: 김규훜 | B17: 2015 | C17: ESTJ | D17: rbgns0105@gmail.com | E17: 야전·실무형(R) | F17: 귀하의 진로적성검사 결과를 종합하면 야전·실무형(R) 성향이 두드러지며, 이는 장비 운용과 현장 중심의 임무 수행에서 강점을 보이는 전형적인 야전형 장교로 성장할 가능성을 의미합니다. 이러한 성향은 군 환경에서 전투장비 운용과 유지관리, 전술적 운용, 병력 통제 등 실제 전투력과 직결되는 분야에서 특히 중요한 역할을 하며, 전투장비를 운용하는 보병(기보)·포병·기갑·방공·육군항공과 같은 전투임무 위주 병과뿐 아니라 공병, 정보통신,화학 등 기술 기반 병과에서도 높은 적합성을 보입니다. 전투병과 특기 선택시는 작전, 군수, 획득분야가 가장 적합합니다. 또한 군수, 병기, 병참, 수송 분야에서도 장비 관리와 운용 능력을 효과적으로 발휘할 수 있습니다. 전문인력 분야로는 통신·공병 등 기술 전문 분야나 무기체계 획득 및 관리와 같은 획득 전문 영역, 장비 중심 연구개발 분야에서도 발전 가능성이 큽니다. 현실형 장교는 전투 및 훈련 상황에서 빠르고 정확한 판단과 실행력을 바탕으로 가시적인 성과를 창출하며, 부하들에게 신뢰를 주는 장점이 있습니다. 다만 단기적 실행에 집중하는 경향으로 인해 장기적 안목 형성과 체계적인 기획 능력, 세밀한 의사소통, 유연한 상황 대응 및 병사 개개인에 대한 심리적 관리 측면에서는 보완이 필요합니다. 따라서 리더형(E, 리더십)이나 행정관리형(C, 정확한 업무수행) 성향을 함께 강화한다면 더욱 높은 성과를 기대할 수 있습니다. | G17: 55 | H17: 41 | I17: 35 | J17: 46 | K17: 54 | L17: 51 | U17: 1Tsh5v1zU8aaV3uMa6QhZkFJKMZnDrrSq | V17: https://drive.google.com/file/d/1Tsh5v1zU8aaV3uMa6QhZkFJKMZnDrrSq/view?usp=drivesdk | W17: =HYPERLINK("https://drive.google.com/file/d/1Tsh5v1zU8aaV3uMa6QhZkFJKMZnDrrSq/view?usp=drivesdk","김규훜_진로적성검사_2026") -> 김규훜_진로적성검사_2026 | X17: Document successfully created; Document successfully merged; PDF created; Run via form trigger as jeongjinung4@gmail.com; Timestamp: Aug 13, 2026 2:24 AM | AA17: SENT | AB17: 46247.643
A18: 테스트 | B18: 1 | C18: 1 | D18: enrud1103@naver.com | E18: 야전·실무형(R) | F18: 귀하의 진로적성검사 결과를 종합하면 야전·실무형(R) 성향이 두드러지며, 이는 장비 운용과 현장 중심의 임무 수행에서 강점을 보이는 전형적인 야전형 장교로 성장할 가능성을 의미합니다. 이러한 성향은 군 환경에서 전투장비 운용과 유지관리, 전술적 운용, 병력 통제 등 실제 전투력과 직결되는 분야에서 특히 중요한 역할을 하며, 전투장비를 운용하는 보병(기보)·포병·기갑·방공·육군항공과 같은 전투임무 위주 병과뿐 아니라 공병, 정보통신,화학 등 기술 기반 병과에서도 높은 적합성을 보입니다. 전투병과 특기 선택시는 작전, 군수, 획득분야가 가장 적합합니다. 또한 군수, 병기, 병참, 수송 분야에서도 장비 관리와 운용 능력을 효과적으로 발휘할 수 있습니다. 전문인력 분야로는 통신·공병 등 기술 전문 분야나 무기체계 획득 및 관리와 같은 획득 전문 영역, 장비 중심 연구개발 분야에서도 발전 가능성이 큽니다. 현실형 장교는 전투 및 훈련 상황에서 빠르고 정확한 판단과 실행력을 바탕으로 가시적인 성과를 창출하며, 부하들에게 신뢰를 주는 장점이 있습니다. 다만 단기적 실행에 집중하는 경향으로 인해 장기적 안목 형성과 체계적인 기획 능력, 세밀한 의사소통, 유연한 상황 대응 및 병사 개개인에 대한 심리적 관리 측면에서는 보완이 필요합니다. 따라서 리더형(E, 리더십)이나 행정관리형(C, 정확한 업무수행) 성향을 함께 강화한다면 더욱 높은 성과를 기대할 수 있습니다. | G18: 60 | H18: 60 | I18: 60 | J18: 60 | K18: 60 | L18: 60 | U18: 136s1UfcENWMfxvFHnoKav6jDj-SSUzdY | V18: https://drive.google.com/file/d/136s1UfcENWMfxvFHnoKav6jDj-SSUzdY/view?usp=drivesdk | W18: =HYPERLINK("https://drive.google.com/file/d/136s1UfcENWMfxvFHnoKav6jDj-SSUzdY/view?usp=drivesdk","테스트_진로적성검사_2026") -> 테스트_진로적성검사_2026 | X18: Document successfully created; Document successfully merged; PDF created; Run via form trigger as jeongjinung4@gmail.com; Timestamp: Aug 13, 2026 4:07 AM | AA18: SENT | AB18: 46247.714
A19: 유성혁 | B19: 2025 | C19: ESTJ | D19: kimnummun@gmail.com | E19: 관계형(S) | F19: 귀하의 검사 결과, 관계형(S) 성향이 중심적으로 나타났습니다. 사람을 이해하고 돕는 데 강점을 가진 유형으로, 조직 내 안정과 협력을 이끄는 중요한 역할을 수행합니다. 귀하에게는 전투병과(인사특기, 작전특기), 인사행정, 정훈, 군의, 의정, 간호 분야가 적합하여, 대인관계 중심 역할에서 역량을 발휘할 수 있습니다. 전문인력 분야에서는 정책전문(교육, 복지 및 인사 정책), 국제전문(협력 및 교류), 교육·교수 중심의 특수전문 분야가 적합합니다. 향후에는 조직 운영 능력을 강화하는 것이 중요합니다. 야전·실무형(R, 병력 및 장비운용)과 리더형(E,리더십) 성향을 함께 발전시키면 지휘 및 관리 역할에서도 큰 강점을 발휘할 수 있습니다. 위에서 추천드린 전투병과(인사특기, 작전특기)는 지휘관 직위를 필수로 이수해야 하므로 야전부대 현장 감각을 유지하며 리더십 함양에도 힘써야 합니다. | G19: 47 | H19: 54 | I19: 43 | J19: 60 | K19: 60 | L19: 57 | U19: 1wrUIK_BVu3RxQTNqwEnHjM76J4fFQJ-- | V19: https://drive.google.com/file/d/1wrUIK_BVu3RxQTNqwEnHjM76J4fFQJ--/view?usp=drivesdk | W19: =HYPERLINK("https://drive.google.com/file/d/1wrUIK_BVu3RxQTNqwEnHjM76J4fFQJ--/view?usp=drivesdk","유성혁_진로적성검사_2026") -> 유성혁_진로적성검사_2026 | X19: Document successfully created; Document successfully merged; PDF created; Run via form trigger as jeongjinung4@gmail.com; Timestamp: Aug 13, 2026 4:09 AM | AA19: SENT | AB19: 46247.715
A20: 전태은 | B20: 2025 | C20: ESFP | D20: jte0506@naver.com | E20: 야전·실무형(R) | F20: 귀하의 진로적성검사 결과를 종합하면 야전·실무형(R) 성향이 두드러지며, 이는 장비 운용과 현장 중심의 임무 수행에서 강점을 보이는 전형적인 야전형 장교로 성장할 가능성을 의미합니다. 이러한 성향은 군 환경에서 전투장비 운용과 유지관리, 전술적 운용, 병력 통제 등 실제 전투력과 직결되는 분야에서 특히 중요한 역할을 하며, 전투장비를 운용하는 보병(기보)·포병·기갑·방공·육군항공과 같은 전투임무 위주 병과뿐 아니라 공병, 정보통신,화학 등 기술 기반 병과에서도 높은 적합성을 보입니다. 전투병과 특기 선택시는 작전, 군수, 획득분야가 가장 적합합니다. 또한 군수, 병기, 병참, 수송 분야에서도 장비 관리와 운용 능력을 효과적으로 발휘할 수 있습니다. 전문인력 분야로는 통신·공병 등 기술 전문 분야나 무기체계 획득 및 관리와 같은 획득 전문 영역, 장비 중심 연구개발 분야에서도 발전 가능성이 큽니다. 현실형 장교는 전투 및 훈련 상황에서 빠르고 정확한 판단과 실행력을 바탕으로 가시적인 성과를 창출하며, 부하들에게 신뢰를 주는 장점이 있습니다. 다만 단기적 실행에 집중하는 경향으로 인해 장기적 안목 형성과 체계적인 기획 능력, 세밀한 의사소통, 유연한 상황 대응 및 병사 개개인에 대한 심리적 관리 측면에서는 보완이 필요합니다. 따라서 리더형(E, 리더십)이나 행정관리형(C, 정확한 업무수행) 성향을 함께 강화한다면 더욱 높은 성과를 기대할 수 있습니다. | G20: 48 | H20: 48 | I20: 48 | J20: 48 | K20: 48 | L20: 48 | U20: 1NtRpzjcjaGEIr4IGqFBkpxzowl0DtJ6z | V20: https://drive.google.com/file/d/1NtRpzjcjaGEIr4IGqFBkpxzowl0DtJ6z/view?usp=drivesdk | W20: =HYPERLINK("https://drive.google.com/file/d/1NtRpzjcjaGEIr4IGqFBkpxzowl0DtJ6z/view?usp=drivesdk","전태은_진로적성검사_2026") -> 전태은_진로적성검사_2026 | X20: Document successfully created; Document successfully merged; PDF created; Run via form trigger as jeongjinung4@gmail.com; Timestamp: Aug 13, 2026 4:09 AM | AA20: SENT | AB20: 46247.715
A21: 이재완 | B21: 2006 | C21: INTJ | D21: sdh220216@sdh.hs.kr | E21: 기술·분석형(I) | F21: 귀하의 검사 결과, 기술·분석형(I) 성향이 중심적으로 나타났습니다. 분석적 사고와 문제 해결 능력이 뛰어나며, 복잡한 시스템과 정보를 이해하고 활용하는 데 강점을 지닌 유형입니다. 군에서는 이러한 능력이 정보전, 기술전, 미래전 수행에 핵심적으로 활용됩니다. 귀하에게는 정보, 정보통신, 화학 병과 등이 특히 적합하며, 기술적 분석이 요구되는 공병 및 항공 분야에서도 역량을 발휘할 수 있습니다. 전문인력 분야에서는 사이버, 연구개발, 국방분석 등 특수전문 영역이 적합하며, 정책전문이나 국제전문 분야에서도 분석 기반 의사결정 능력을 활용할 수 있습니다. 향후에는 기술적 이해뿐 아니라 야전에서 실제 적용 능력을 함께 강화하는 것이 중요합니다. 야전·실무형(R, 현장감각)이나 행정관리형(C, 체계적 업무수행) 성향을 보완한다면 실무와 분석을 겸비한 핵심 인재로 성장할 수 있습니다. 그러나 현상 분석에 집중하는 경향으로 인해 의사결정이 지연되거나 실행력이 부족해질 수 있음을 유의해야 합니다. 위에서 추천드린 병과 역시 지휘관 직위를 필수로 이수해야 하므로 야전부대 현장 감각을 유지하고 의사소통 및 대인관계 형성과 같은 리더십을 함양에도 힘써야 합니다. | G21: 33 | H21: 37 | I21: 34 | J21: 25 | K21: 21 | L21: 28 | U21: 1EG1AAZhDO1U1O0sBfGT_iQ_nD5s4TCeW | V21: https://drive.google.com/file/d/1EG1AAZhDO1U1O0sBfGT_iQ_nD5s4TCeW/view?usp=drivesdk | W21: =HYPERLINK("https://drive.google.com/file/d/1EG1AAZhDO1U1O0sBfGT_iQ_nD5s4TCeW/view?usp=drivesdk","이재완_진로적성검사_2026") -> 이재완_진로적성검사_2026 | X21: Document successfully created; Document successfully merged; PDF created; Run via form trigger as jeongjinung4@gmail.com; Timestamp: Aug 13, 2026 4:09 AM | AA21: SENT | AB21: 46247.764
A22: 장재혁 | B22: 2021 | C22: INFJ | D22: wkdwogur1201@naver.com | E22: 리더형(E) | F22: 귀하의 검사 결과, 리더형(E) 성향이 강하게 나타났습니다. 리더십과 의사결정 능력(협의, 조정)이 뛰어나며, 조직을 이끌고 목표를 달성하는 데 강점을 가진 유형입니다. 또한 이 유형은 상황을 빠르게 파악하고 방향을 설정하여 조직을 이끄는 능력이 뛰어나며, 부하들을 동기부여하고 목표 달성을 위해 자원을 효과적으로 배분하는 데 능숙합니다. 군에서는 이러한 성향이 지휘관 역할과 직결됩니다. 귀하에게는 보병, 포병, 기갑 등 모든 전투 병과에서의 전투부대 지휘 역할에 적합하여 조직 관리 능력을 발휘할 수 있습니다. 전문인력 분야에서는 정책전문, 국제전문(무관 등), 획득전문(방위사업 관련) 분야가 적합합니다. 향후에는 단순한 리더십을 넘어 전문성과 현장 이해를 함께 갖추는 것이 중요합니다. 야전·실무형(R,현장감각)이나 관계형(S,대인관계) 성향을 보완한다면 더욱 균형 잡힌 지휘관으로 성장할 수 있습니다. 또한 전투병과 장교는 지휘관과 참모직위를 모두 이수해야 하므로 참모로서의 섬세함과 업무관리 능력을 함양해야 한다. | G22: 44 | H22: 47 | I22: 42 | J22: 56 | K22: 57 | L22: 54 | U22: 1DE4QtkZwpBnKAaW8Ed-cUcGgNeNA6qWp | V22: https://drive.google.com/file/d/1DE4QtkZwpBnKAaW8Ed-cUcGgNeNA6qWp/view?usp=drivesdk | W22: =HYPERLINK("https://drive.google.com/file/d/1DE4QtkZwpBnKAaW8Ed-cUcGgNeNA6qWp/view?usp=drivesdk","장재혁_진로적성검사_2026") -> 장재혁_진로적성검사_2026 | X22: Document successfully created; Document successfully merged; PDF created; Run via form trigger as jeongjinung4@gmail.com; Timestamp: Aug 13, 2026 5:20 AM | AA22: SENT | AB22: 46247.794
A23: 박종민 | B23: 2507 | C23: ESTP | D23: sunlight6543@naver.com | E23: 리더형(E) | F23: 귀하의 검사 결과, 리더형(E) 성향이 강하게 나타났습니다. 리더십과 의사결정 능력(협의, 조정)이 뛰어나며, 조직을 이끌고 목표를 달성하는 데 강점을 가진 유형입니다. 또한 이 유형은 상황을 빠르게 파악하고 방향을 설정하여 조직을 이끄는 능력이 뛰어나며, 부하들을 동기부여하고 목표 달성을 위해 자원을 효과적으로 배분하는 데 능숙합니다. 군에서는 이러한 성향이 지휘관 역할과 직결됩니다. 귀하에게는 보병, 포병, 기갑 등 모든 전투 병과에서의 전투부대 지휘 역할에 적합하여 조직 관리 능력을 발휘할 수 있습니다. 전문인력 분야에서는 정책전문, 국제전문(무관 등), 획득전문(방위사업 관련) 분야가 적합합니다. 향후에는 단순한 리더십을 넘어 전문성과 현장 이해를 함께 갖추는 것이 중요합니다. 야전·실무형(R,현장감각)이나 관계형(S,대인관계) 성향을 보완한다면 더욱 균형 잡힌 지휘관으로 성장할 수 있습니다. 또한 전투병과 장교는 지휘관과 참모직위를 모두 이수해야 하므로 참모로서의 섬세함과 업무관리 능력을 함양해야 한다. | G23: 51 | H23: 53 | I23: 50 | J23: 59 | K23: 60 | L23: 54 | U23: 19mpL21eoVjRAqB-FaBYRwntS_k2Vb-om | V23: https://drive.google.com/file/d/19mpL21eoVjRAqB-FaBYRwntS_k2Vb-om/view?usp=drivesdk | W23: =HYPERLINK("https://drive.google.com/file/d/19mpL21eoVjRAqB-FaBYRwntS_k2Vb-om/view?usp=drivesdk","박종민_진로적성검사_2026") -> 박종민_진로적성검사_2026 | X23: Document successfully created; Document successfully merged; PDF created; Run via form trigger as jeongjinung4@gmail.com; Timestamp: Aug 13, 2026 6:03 AM | AA23: SENT | AB23: 46247.834
A24: 문관우 | B24: 2026 | C24: INTP | D24: qwersadzaee@gmail.com | E24: 야전·실무형(R) | F24: 귀하의 진로적성검사 결과를 종합하면 야전·실무형(R) 성향이 두드러지며, 이는 장비 운용과 현장 중심의 임무 수행에서 강점을 보이는 전형적인 야전형 장교로 성장할 가능성을 의미합니다. 이러한 성향은 군 환경에서 전투장비 운용과 유지관리, 전술적 운용, 병력 통제 등 실제 전투력과 직결되는 분야에서 특히 중요한 역할을 하며, 전투장비를 운용하는 보병(기보)·포병·기갑·방공·육군항공과 같은 전투임무 위주 병과뿐 아니라 공병, 정보통신,화학 등 기술 기반 병과에서도 높은 적합성을 보입니다. 전투병과 특기 선택시는 작전, 군수, 획득분야가 가장 적합합니다. 또한 군수, 병기, 병참, 수송 분야에서도 장비 관리와 운용 능력을 효과적으로 발휘할 수 있습니다. 전문인력 분야로는 통신·공병 등 기술 전문 분야나 무기체계 획득 및 관리와 같은 획득 전문 영역, 장비 중심 연구개발 분야에서도 발전 가능성이 큽니다. 현실형 장교는 전투 및 훈련 상황에서 빠르고 정확한 판단과 실행력을 바탕으로 가시적인 성과를 창출하며, 부하들에게 신뢰를 주는 장점이 있습니다. 다만 단기적 실행에 집중하는 경향으로 인해 장기적 안목 형성과 체계적인 기획 능력, 세밀한 의사소통, 유연한 상황 대응 및 병사 개개인에 대한 심리적 관리 측면에서는 보완이 필요합니다. 따라서 리더형(E, 리더십)이나 행정관리형(C, 정확한 업무수행) 성향을 함께 강화한다면 더욱 높은 성과를 기대할 수 있습니다. | G24: 37 | H24: 36 | I24: 36 | J24: 35 | K24: 36 | L24: 37 | U24: 14zxTxPQ3MvRRc_1q6HNJ5U4DlsuWNW_h | V24: https://drive.google.com/file/d/14zxTxPQ3MvRRc_1q6HNJ5U4DlsuWNW_h/view?usp=drivesdk | W24: =HYPERLINK("https://drive.google.com/file/d/14zxTxPQ3MvRRc_1q6HNJ5U4DlsuWNW_h/view?usp=drivesdk","문관우_진로적성검사_2026") -> 문관우_진로적성검사_2026 | X24: Document successfully created; Document successfully merged; PDF created; Run via form trigger as jeongjinung4@gmail.com; Timestamp: Aug 13, 2026 6:04 AM | AA24: SENT | AB24: 46247.834
A25: 문관우 | B25: 2026 | C25: INTP | D25: qwersadzaee@gmail.com | E25: 창의형(A) | F25: 귀하의 진로적성검사 결과, 창의형(A) 성향이 높게 나타났습니다. 창의적인 표현과 방법, 새로운 아이디어를 통해 조직에 활력을 불어넣는 역할을 합니다. 군 조직에서는 이러한 성향이 장병 사기진작, 홍보, 심리전, 문화 활동 등에서 중요한 의미를 갖습니다. 귀하에게는 전투병과 인사특기,정훈병과가 적합하며, 인사근무 및 사기진작 활동, 영상 제작 및 콘텐츠 기획을 통한 군 홍보활동 등의 분야에서 강점을 발휘할 수 있습니다. 또한 인사행정이나 군사경찰 기능 중 일부 분야에서도 창의적 역할을 수행할 수 있습니다. 전문인력 분야에서는 정책전문(국방정책 홍보) 또는 국방홍보원 등의 미디어 분야로의 확장이 가능합니다. 군 조직 특성상 기본적인 규율과 체계 적응이 중요하므로, 행정관리형(C, 규율중시, 정확성)이나 관계형(S, 협업관계) 역량을 함께 보완한다면 보다 안정적인 성과를 낼 수 있습니다. 위에서 추천드린 전투병과(인사특기), 군사경찰 병과 역시 지휘관 직위를 필수로 이수해야 하므로 야전부대 현장 감각을 유지하고 의사소통 및 대인관계 형성과 같은 리더십을 함양에도 힘써야 합니다. | G25: 44 | H25: 38 | I25: 46 | J25: 40 | K25: 45 | L25: 39 | U25: 1GwZ0WUnW2cveojqlO3GJM8853HxpjiBw | V25: https://drive.google.com/file/d/1GwZ0WUnW2cveojqlO3GJM8853HxpjiBw/view?usp=drivesdk | W25: =HYPERLINK("https://drive.google.com/file/d/1GwZ0WUnW2cveojqlO3GJM8853HxpjiBw/view?usp=drivesdk","문관우_진로적성검사_2026") -> 문관우_진로적성검사_2026 | X25: Document successfully created; Document successfully merged; PDF created; Run via form trigger as jeongjinung4@gmail.com; Timestamp: Aug 13, 2026 7:00 AM | AA25: SENT | AB25: 46247.922
A26: 하연 | B26: 2027 | C26: ESFP | D26: namhayeon7648@gmail.com | E26: 관계형(S) | F26: 귀하의 검사 결과, 관계형(S) 성향이 중심적으로 나타났습니다. 사람을 이해하고 돕는 데 강점을 가진 유형으로, 조직 내 안정과 협력을 이끄는 중요한 역할을 수행합니다. 귀하에게는 전투병과(인사특기, 작전특기), 인사행정, 정훈, 군의, 의정, 간호 분야가 적합하여, 대인관계 중심 역할에서 역량을 발휘할 수 있습니다. 전문인력 분야에서는 정책전문(교육, 복지 및 인사 정책), 국제전문(협력 및 교류), 교육·교수 중심의 특수전문 분야가 적합합니다. 향후에는 조직 운영 능력을 강화하는 것이 중요합니다. 야전·실무형(R, 병력 및 장비운용)과 리더형(E,리더십) 성향을 함께 발전시키면 지휘 및 관리 역할에서도 큰 강점을 발휘할 수 있습니다. 위에서 추천드린 전투병과(인사특기, 작전특기)는 지휘관 직위를 필수로 이수해야 하므로 야전부대 현장 감각을 유지하며 리더십 함양에도 힘써야 합니다. | G26: 33 | H26: 24 | I26: 31 | J26: 47 | K26: 35 | L26: 43 | U26: 1YIJ0wZtxKshozQoATUjV6IZDLgxMoxNB | V26: https://drive.google.com/file/d/1YIJ0wZtxKshozQoATUjV6IZDLgxMoxNB/view?usp=drivesdk | W26: =HYPERLINK("https://drive.google.com/file/d/1YIJ0wZtxKshozQoATUjV6IZDLgxMoxNB/view?usp=drivesdk","하연_진로적성검사_2026") -> 하연_진로적성검사_2026 | X26: Document successfully created; Document successfully merged; PDF created; Run via form trigger as jeongjinung4@gmail.com; Timestamp: Aug 13, 2026 9:08 AM | AA26: SENT | AB26: 46248.005
A27: 안문기 | B27: 2026 | C27: INFJ | D27: mungiahn@gmail.com | E27: 관계형(S) | F27: 귀하의 검사 결과, 관계형(S) 성향이 중심적으로 나타났습니다. 사람을 이해하고 돕는 데 강점을 가진 유형으로, 조직 내 안정과 협력을 이끄는 중요한 역할을 수행합니다. 귀하에게는 전투병과(인사특기, 작전특기), 인사행정, 정훈, 군의, 의정, 간호 분야가 적합하여, 대인관계 중심 역할에서 역량을 발휘할 수 있습니다. 전문인력 분야에서는 정책전문(교육, 복지 및 인사 정책), 국제전문(협력 및 교류), 교육·교수 중심의 특수전문 분야가 적합합니다. 향후에는 조직 운영 능력을 강화하는 것이 중요합니다. 야전·실무형(R, 병력 및 장비운용)과 리더형(E,리더십) 성향을 함께 발전시키면 지휘 및 관리 역할에서도 큰 강점을 발휘할 수 있습니다. 위에서 추천드린 전투병과(인사특기, 작전특기)는 지휘관 직위를 필수로 이수해야 하므로 야전부대 현장 감각을 유지하며 리더십 함양에도 힘써야 합니다. | G27: 48 | H27: 45 | I27: 49 | J27: 58 | K27: 41 | L27: 49 | U27: 1eHVr0Mm4g-8SmMXuaSnj5YxlLyQunRDo | V27: https://drive.google.com/file/d/1eHVr0Mm4g-8SmMXuaSnj5YxlLyQunRDo/view?usp=drivesdk | W27: =HYPERLINK("https://drive.google.com/file/d/1eHVr0Mm4g-8SmMXuaSnj5YxlLyQunRDo/view?usp=drivesdk","안문기_진로적성검사_2026") -> 안문기_진로적성검사_2026 | X27: Document successfully created; Document successfully merged; PDF created; Run via form trigger as jeongjinung4@gmail.com; Timestamp: Aug 13, 2026 11:07 AM | AA27: SENT | AB27: 46248.3
A28: 최승준 | B28: 2013 | C28: ENTJ | D28: paoyusha@naver.com | E28: 관계형(S) | F28: 귀하의 검사 결과, 관계형(S) 성향이 중심적으로 나타났습니다. 사람을 이해하고 돕는 데 강점을 가진 유형으로, 조직 내 안정과 협력을 이끄는 중요한 역할을 수행합니다. 귀하에게는 전투병과(인사특기, 작전특기), 인사행정, 정훈, 군의, 의정, 간호 분야가 적합하여, 대인관계 중심 역할에서 역량을 발휘할 수 있습니다. 전문인력 분야에서는 정책전문(교육, 복지 및 인사 정책), 국제전문(협력 및 교류), 교육·교수 중심의 특수전문 분야가 적합합니다. 향후에는 조직 운영 능력을 강화하는 것이 중요합니다. 야전·실무형(R, 병력 및 장비운용)과 리더형(E,리더십) 성향을 함께 발전시키면 지휘 및 관리 역할에서도 큰 강점을 발휘할 수 있습니다. 위에서 추천드린 전투병과(인사특기, 작전특기)는 지휘관 직위를 필수로 이수해야 하므로 야전부대 현장 감각을 유지하며 리더십 함양에도 힘써야 합니다. | G28: 49 | H28: 51 | I28: 48 | J28: 52 | K28: 50 | L28: 48 | U28: 1X0KgZDyD53aIGLnYvXS84Aqd1vONC87a | V28: https://drive.google.com/file/d/1X0KgZDyD53aIGLnYvXS84Aqd1vONC87a/view?usp=drivesdk | W28: =HYPERLINK("https://drive.google.com/file/d/1X0KgZDyD53aIGLnYvXS84Aqd1vONC87a/view?usp=drivesdk","최승준_진로적성검사_2026") -> 최승준_진로적성검사_2026 | X28: Document successfully created; Document successfully merged; PDF created; Run via form trigger as jeongjinung4@gmail.com; Timestamp: Aug 13, 2026 6:12 PM | AA28: SENT | AB28: 46248.325
A29: 테스트 | B29: 1 | C29: 1 | D29: kclee1982@naver.com | E29: 야전·실무형(R) | F29: 귀하의 진로적성검사 결과를 종합하면 야전·실무형(R) 성향이 두드러지며, 이는 장비 운용과 현장 중심의 임무 수행에서 강점을 보이는 전형적인 야전형 장교로 성장할 가능성을 의미합니다. 이러한 성향은 군 환경에서 전투장비 운용과 유지관리, 전술적 운용, 병력 통제 등 실제 전투력과 직결되는 분야에서 특히 중요한 역할을 하며, 전투장비를 운용하는 보병(기보)·포병·기갑·방공·육군항공과 같은 전투임무 위주 병과뿐 아니라 공병, 정보통신,화학 등 기술 기반 병과에서도 높은 적합성을 보입니다. 전투병과 특기 선택시는 작전, 군수, 획득분야가 가장 적합합니다. 또한 군수, 병기, 병참, 수송 분야에서도 장비 관리와 운용 능력을 효과적으로 발휘할 수 있습니다. 전문인력 분야로는 통신·공병 등 기술 전문 분야나 무기체계 획득 및 관리와 같은 획득 전문 영역, 장비 중심 연구개발 분야에서도 발전 가능성이 큽니다. 현실형 장교는 전투 및 훈련 상황에서 빠르고 정확한 판단과 실행력을 바탕으로 가시적인 성과를 창출하며, 부하들에게 신뢰를 주는 장점이 있습니다. 다만 단기적 실행에 집중하는 경향으로 인해 장기적 안목 형성과 체계적인 기획 능력, 세밀한 의사소통, 유연한 상황 대응 및 병사 개개인에 대한 심리적 관리 측면에서는 보완이 필요합니다. 따라서 리더형(E, 리더십)이나 행정관리형(C, 정확한 업무수행) 성향을 함께 강화한다면 더욱 높은 성과를 기대할 수 있습니다. | G29: 36 | H29: 36 | I29: 36 | J29: 36 | K29: 36 | L29: 36 | U29: 1_M88-xln3-IFqfZcS2BcAQbpiwWSn0fg | V29: https://drive.google.com/file/d/1_M88-xln3-IFqfZcS2BcAQbpiwWSn0fg/view?usp=drivesdk | W29: =HYPERLINK("https://drive.google.com/file/d/1_M88-xln3-IFqfZcS2BcAQbpiwWSn0fg/view?usp=drivesdk","테스트_진로적성검사_2026") -> 테스트_진로적성검사_2026 | X29: Document successfully created; Document successfully merged; PDF created; Run via form trigger as jeongjinung4@gmail.com; Timestamp: Aug 13, 2026 6:48 PM | AA29: SENT | AB29: 46248.334
A30: 테스트 | B30: 2025 | C30: ESTJ | D30: kimnummun@gmail.com | E30: 야전·실무형(R) | F30: 귀하의 진로적성검사 결과를 종합하면 야전·실무형(R) 성향이 두드러지며, 이는 장비 운용과 현장 중심의 임무 수행에서 강점을 보이는 전형적인 야전형 장교로 성장할 가능성을 의미합니다. 이러한 성향은 군 환경에서 전투장비 운용과 유지관리, 전술적 운용, 병력 통제 등 실제 전투력과 직결되는 분야에서 특히 중요한 역할을 하며, 전투장비를 운용하는 보병(기보)·포병·기갑·방공·육군항공과 같은 전투임무 위주 병과뿐 아니라 공병, 정보통신,화학 등 기술 기반 병과에서도 높은 적합성을 보입니다. 전투병과 특기 선택시는 작전, 군수, 획득분야가 가장 적합합니다. 또한 군수, 병기, 병참, 수송 분야에서도 장비 관리와 운용 능력을 효과적으로 발휘할 수 있습니다. 전문인력 분야로는 통신·공병 등 기술 전문 분야나 무기체계 획득 및 관리와 같은 획득 전문 영역, 장비 중심 연구개발 분야에서도 발전 가능성이 큽니다. 현실형 장교는 전투 및 훈련 상황에서 빠르고 정확한 판단과 실행력을 바탕으로 가시적인 성과를 창출하며, 부하들에게 신뢰를 주는 장점이 있습니다. 다만 단기적 실행에 집중하는 경향으로 인해 장기적 안목 형성과 체계적인 기획 능력, 세밀한 의사소통, 유연한 상황 대응 및 병사 개개인에 대한 심리적 관리 측면에서는 보완이 필요합니다. 따라서 리더형(E, 리더십)이나 행정관리형(C, 정확한 업무수행) 성향을 함께 강화한다면 더욱 높은 성과를 기대할 수 있습니다. | G30: 60 | H30: 60 | I30: 60 | J30: 60 | K30: 60 | L30: 60 | U30: 1NvaLCat0cTBBCHY5brZsBArx3egcRzXL | V30: https://drive.google.com/file/d/1NvaLCat0cTBBCHY5brZsBArx3egcRzXL/view?usp=drivesdk | W30: =HYPERLINK("https://drive.google.com/file/d/1NvaLCat0cTBBCHY5brZsBArx3egcRzXL/view?usp=drivesdk","테스트_진로적성검사_2026") -> 테스트_진로적성검사_2026 | X30: Document successfully created; Document successfully merged; PDF created; Run via form trigger as jeongjinung4@gmail.com; Timestamp: Aug 13, 2026 7:00 PM | AA30: SENT | AB30: 46248.338
A31: 테스트 | B31: 1 | C31: 1 | D31: enrud1103@naver.com | E31: 야전·실무형(R) | F31: 귀하의 진로적성검사 결과를 종합하면 야전·실무형(R) 성향이 두드러지며, 이는 장비 운용과 현장 중심의 임무 수행에서 강점을 보이는 전형적인 야전형 장교로 성장할 가능성을 의미합니다. 이러한 성향은 군 환경에서 전투장비 운용과 유지관리, 전술적 운용, 병력 통제 등 실제 전투력과 직결되는 분야에서 특히 중요한 역할을 하며, 전투장비를 운용하는 보병(기보)·포병·기갑·방공·육군항공과 같은 전투임무 위주 병과뿐 아니라 공병, 정보통신,화학 등 기술 기반 병과에서도 높은 적합성을 보입니다. 전투병과 특기 선택시는 작전, 군수, 획득분야가 가장 적합합니다. 또한 군수, 병기, 병참, 수송 분야에서도 장비 관리와 운용 능력을 효과적으로 발휘할 수 있습니다. 전문인력 분야로는 통신·공병 등 기술 전문 분야나 무기체계 획득 및 관리와 같은 획득 전문 영역, 장비 중심 연구개발 분야에서도 발전 가능성이 큽니다. 현실형 장교는 전투 및 훈련 상황에서 빠르고 정확한 판단과 실행력을 바탕으로 가시적인 성과를 창출하며, 부하들에게 신뢰를 주는 장점이 있습니다. 다만 단기적 실행에 집중하는 경향으로 인해 장기적 안목 형성과 체계적인 기획 능력, 세밀한 의사소통, 유연한 상황 대응 및 병사 개개인에 대한 심리적 관리 측면에서는 보완이 필요합니다. 따라서 리더형(E, 리더십)이나 행정관리형(C, 정확한 업무수행) 성향을 함께 강화한다면 더욱 높은 성과를 기대할 수 있습니다. | G31: 36 | H31: 36 | I31: 36 | J31: 36 | K31: 36 | L31: 36 | U31: 1TwQLy568Q3xzdfapdaPviFdKCaomjeoX | V31: https://drive.google.com/file/d/1TwQLy568Q3xzdfapdaPviFdKCaomjeoX/view?usp=drivesdk | W31: =HYPERLINK("https://drive.google.com/file/d/1TwQLy568Q3xzdfapdaPviFdKCaomjeoX/view?usp=drivesdk","테스트_진로적성검사_2026") -> 테스트_진로적성검사_2026 | X31: Document successfully created; Document successfully merged; PDF created; Run via form trigger as jeongjinung4@gmail.com; Timestamp: Aug 13, 2026 7:07 PM | AA31: SENT | AB31: 46248.343
A32: 규훈 | B32: 2020 | C32: ckdjf | D32: rbgns0105@gmail.com | E32: 야전·실무형(R) | F32: 귀하의 진로적성검사 결과를 종합하면 야전·실무형(R) 성향이 두드러지며, 이는 장비 운용과 현장 중심의 임무 수행에서 강점을 보이는 전형적인 야전형 장교로 성장할 가능성을 의미합니다. 이러한 성향은 군 환경에서 전투장비 운용과 유지관리, 전술적 운용, 병력 통제 등 실제 전투력과 직결되는 분야에서 특히 중요한 역할을 하며, 전투장비를 운용하는 보병(기보)·포병·기갑·방공·육군항공과 같은 전투임무 위주 병과뿐 아니라 공병, 정보통신,화학 등 기술 기반 병과에서도 높은 적합성을 보입니다. 전투병과 특기 선택시는 작전, 군수, 획득분야가 가장 적합합니다. 또한 군수, 병기, 병참, 수송 분야에서도 장비 관리와 운용 능력을 효과적으로 발휘할 수 있습니다. 전문인력 분야로는 통신·공병 등 기술 전문 분야나 무기체계 획득 및 관리와 같은 획득 전문 영역, 장비 중심 연구개발 분야에서도 발전 가능성이 큽니다. 현실형 장교는 전투 및 훈련 상황에서 빠르고 정확한 판단과 실행력을 바탕으로 가시적인 성과를 창출하며, 부하들에게 신뢰를 주는 장점이 있습니다. 다만 단기적 실행에 집중하는 경향으로 인해 장기적 안목 형성과 체계적인 기획 능력, 세밀한 의사소통, 유연한 상황 대응 및 병사 개개인에 대한 심리적 관리 측면에서는 보완이 필요합니다. 따라서 리더형(E, 리더십)이나 행정관리형(C, 정확한 업무수행) 성향을 함께 강화한다면 더욱 높은 성과를 기대할 수 있습니다. | G32: 38 | H32: 27 | I32: 36 | J32: 32 | K32: 30 | L32: 32 | U32: 1J_xXkWguuyqhNOm1bh22tcs9hQGrBeg2 | V32: https://drive.google.com/file/d/1J_xXkWguuyqhNOm1bh22tcs9hQGrBeg2/view?usp=drivesdk | W32: =HYPERLINK("https://drive.google.com/file/d/1J_xXkWguuyqhNOm1bh22tcs9hQGrBeg2/view?usp=drivesdk","규훈_진로적성검사_2026") -> 규훈_진로적성검사_2026 | X32: Document successfully created; Document successfully merged; PDF created; Run via form trigger as jeongjinung4@gmail.com; Timestamp: Aug 13, 2026 7:13 PM | AA32: SENT | AB32: 46248.343
A33: 전태은 | B33: 2025 | C33: ESFP | D33: jte0506@naver.com | E33: 야전·실무형(R) | F33: 귀하의 진로적성검사 결과를 종합하면 야전·실무형(R) 성향이 두드러지며, 이는 장비 운용과 현장 중심의 임무 수행에서 강점을 보이는 전형적인 야전형 장교로 성장할 가능성을 의미합니다. 이러한 성향은 군 환경에서 전투장비 운용과 유지관리, 전술적 운용, 병력 통제 등 실제 전투력과 직결되는 분야에서 특히 중요한 역할을 하며, 전투장비를 운용하는 보병(기보)·포병·기갑·방공·육군항공과 같은 전투임무 위주 병과뿐 아니라 공병, 정보통신,화학 등 기술 기반 병과에서도 높은 적합성을 보입니다. 전투병과 특기 선택시는 작전, 군수, 획득분야가 가장 적합합니다. 또한 군수, 병기, 병참, 수송 분야에서도 장비 관리와 운용 능력을 효과적으로 발휘할 수 있습니다. 전문인력 분야로는 통신·공병 등 기술 전문 분야나 무기체계 획득 및 관리와 같은 획득 전문 영역, 장비 중심 연구개발 분야에서도 발전 가능성이 큽니다. 현실형 장교는 전투 및 훈련 상황에서 빠르고 정확한 판단과 실행력을 바탕으로 가시적인 성과를 창출하며, 부하들에게 신뢰를 주는 장점이 있습니다. 다만 단기적 실행에 집중하는 경향으로 인해 장기적 안목 형성과 체계적인 기획 능력, 세밀한 의사소통, 유연한 상황 대응 및 병사 개개인에 대한 심리적 관리 측면에서는 보완이 필요합니다. 따라서 리더형(E, 리더십)이나 행정관리형(C, 정확한 업무수행) 성향을 함께 강화한다면 더욱 높은 성과를 기대할 수 있습니다. | G33: 48 | H33: 48 | I33: 48 | J33: 48 | K33: 48 | L33: 48 | U33: 1LdBglW9x-r6KoCjeabkaV60baz98bk4r | V33: https://drive.google.com/file/d/1LdBglW9x-r6KoCjeabkaV60baz98bk4r/view?usp=drivesdk | W33: =HYPERLINK("https://drive.google.com/file/d/1LdBglW9x-r6KoCjeabkaV60baz98bk4r/view?usp=drivesdk","전태은_진로적성검사_2026") -> 전태은_진로적성검사_2026 | X33: Document successfully created; Document successfully merged; PDF created; Run via form trigger as jeongjinung4@gmail.com; Timestamp: Aug 13, 2026 7:13 PM | AA33: SENT | AB33: 46248.343
A34: 테스트 | B34: 1 | C34: 1 | D34: enrud1103@naver.com | E34: 야전·실무형(R) | F34: 귀하의 진로적성검사 결과를 종합하면 야전·실무형(R) 성향이 두드러지며, 이는 장비 운용과 현장 중심의 임무 수행에서 강점을 보이는 전형적인 야전형 장교로 성장할 가능성을 의미합니다. 이러한 성향은 군 환경에서 전투장비 운용과 유지관리, 전술적 운용, 병력 통제 등 실제 전투력과 직결되는 분야에서 특히 중요한 역할을 하며, 전투장비를 운용하는 보병(기보)·포병·기갑·방공·육군항공과 같은 전투임무 위주 병과뿐 아니라 공병, 정보통신,화학 등 기술 기반 병과에서도 높은 적합성을 보입니다. 전투병과 특기 선택시는 작전, 군수, 획득분야가 가장 적합합니다. 또한 군수, 병기, 병참, 수송 분야에서도 장비 관리와 운용 능력을 효과적으로 발휘할 수 있습니다. 전문인력 분야로는 통신·공병 등 기술 전문 분야나 무기체계 획득 및 관리와 같은 획득 전문 영역, 장비 중심 연구개발 분야에서도 발전 가능성이 큽니다. 현실형 장교는 전투 및 훈련 상황에서 빠르고 정확한 판단과 실행력을 바탕으로 가시적인 성과를 창출하며, 부하들에게 신뢰를 주는 장점이 있습니다. 다만 단기적 실행에 집중하는 경향으로 인해 장기적 안목 형성과 체계적인 기획 능력, 세밀한 의사소통, 유연한 상황 대응 및 병사 개개인에 대한 심리적 관리 측면에서는 보완이 필요합니다. 따라서 리더형(E, 리더십)이나 행정관리형(C, 정확한 업무수행) 성향을 함께 강화한다면 더욱 높은 성과를 기대할 수 있습니다. | G34: 36 | H34: 36 | I34: 36 | J34: 36 | K34: 36 | L34: 36 | U34: 1qtX5J4hmHNkHb6See4T2NIPA48odeJne | V34: https://drive.google.com/file/d/1qtX5J4hmHNkHb6See4T2NIPA48odeJne/view?usp=drivesdk | W34: =HYPERLINK("https://drive.google.com/file/d/1qtX5J4hmHNkHb6See4T2NIPA48odeJne/view?usp=drivesdk","테스트_진로적성검사_2026") -> 테스트_진로적성검사_2026 | X34: Document successfully created; Document successfully merged; PDF created; Run via form trigger as jeongjinung4@gmail.com; Timestamp: Aug 13, 2026 7:14 PM | AA34: SENT | AB34: 46248.351
A35: 테스트 | B35: 2025 | C35: estj | D35: kimnummun@gmail.com | E35: 야전·실무형(R) | F35: 귀하의 진로적성검사 결과를 종합하면 야전·실무형(R) 성향이 두드러지며, 이는 장비 운용과 현장 중심의 임무 수행에서 강점을 보이는 전형적인 야전형 장교로 성장할 가능성을 의미합니다. 이러한 성향은 군 환경에서 전투장비 운용과 유지관리, 전술적 운용, 병력 통제 등 실제 전투력과 직결되는 분야에서 특히 중요한 역할을 하며, 전투장비를 운용하는 보병(기보)·포병·기갑·방공·육군항공과 같은 전투임무 위주 병과뿐 아니라 공병, 정보통신,화학 등 기술 기반 병과에서도 높은 적합성을 보입니다. 전투병과 특기 선택시는 작전, 군수, 획득분야가 가장 적합합니다. 또한 군수, 병기, 병참, 수송 분야에서도 장비 관리와 운용 능력을 효과적으로 발휘할 수 있습니다. 전문인력 분야로는 통신·공병 등 기술 전문 분야나 무기체계 획득 및 관리와 같은 획득 전문 영역, 장비 중심 연구개발 분야에서도 발전 가능성이 큽니다. 현실형 장교는 전투 및 훈련 상황에서 빠르고 정확한 판단과 실행력을 바탕으로 가시적인 성과를 창출하며, 부하들에게 신뢰를 주는 장점이 있습니다. 다만 단기적 실행에 집중하는 경향으로 인해 장기적 안목 형성과 체계적인 기획 능력, 세밀한 의사소통, 유연한 상황 대응 및 병사 개개인에 대한 심리적 관리 측면에서는 보완이 필요합니다. 따라서 리더형(E, 리더십)이나 행정관리형(C, 정확한 업무수행) 성향을 함께 강화한다면 더욱 높은 성과를 기대할 수 있습니다. | G35: 60 | H35: 60 | I35: 60 | J35: 60 | K35: 60 | L35: 60 | U35: 1mmn1VYuJ7DBoQI2bbBX3uVklLLK1p40f | V35: https://drive.google.com/file/d/1mmn1VYuJ7DBoQI2bbBX3uVklLLK1p40f/view?usp=drivesdk | W35: =HYPERLINK("https://drive.google.com/file/d/1mmn1VYuJ7DBoQI2bbBX3uVklLLK1p40f/view?usp=drivesdk","테스트_진로적성검사_2026") -> 테스트_진로적성검사_2026 | X35: Document successfully created; Document successfully merged; PDF created; Run via form trigger as jeongjinung4@gmail.com; Timestamp: Aug 13, 2026 7:25 PM | AA35: SENT | AB35: 46248.358
A36: 테스트 | B36: 1 | C36: 1 | D36: enrud1103@naver.com | E36: 야전·실무형(R) | F36: 귀하의 진로적성검사 결과를 종합하면 야전·실무형(R) 성향이 두드러지며, 이는 장비 운용과 현장 중심의 임무 수행에서 강점을 보이는 전형적인 야전형 장교로 성장할 가능성을 의미합니다. 이러한 성향은 군 환경에서 전투장비 운용과 유지관리, 전술적 운용, 병력 통제 등 실제 전투력과 직결되는 분야에서 특히 중요한 역할을 하며, 전투장비를 운용하는 보병(기보)·포병·기갑·방공·육군항공과 같은 전투임무 위주 병과뿐 아니라 공병, 정보통신,화학 등 기술 기반 병과에서도 높은 적합성을 보입니다. 전투병과 특기 선택시는 작전, 군수, 획득분야가 가장 적합합니다. 또한 군수, 병기, 병참, 수송 분야에서도 장비 관리와 운용 능력을 효과적으로 발휘할 수 있습니다. 전문인력 분야로는 통신·공병 등 기술 전문 분야나 무기체계 획득 및 관리와 같은 획득 전문 영역, 장비 중심 연구개발 분야에서도 발전 가능성이 큽니다. 현실형 장교는 전투 및 훈련 상황에서 빠르고 정확한 판단과 실행력을 바탕으로 가시적인 성과를 창출하며, 부하들에게 신뢰를 주는 장점이 있습니다. 다만 단기적 실행에 집중하는 경향으로 인해 장기적 안목 형성과 체계적인 기획 능력, 세밀한 의사소통, 유연한 상황 대응 및 병사 개개인에 대한 심리적 관리 측면에서는 보완이 필요합니다. 따라서 리더형(E, 리더십)이나 행정관리형(C, 정확한 업무수행) 성향을 함께 강화한다면 더욱 높은 성과를 기대할 수 있습니다. | G36: 36 | H36: 36 | I36: 36 | J36: 36 | K36: 36 | L36: 36 | U36: 1R5oaXZE5pJqUYPhwmhyJlYt_kShIYPoC | V36: https://drive.google.com/file/d/1R5oaXZE5pJqUYPhwmhyJlYt_kShIYPoC/view?usp=drivesdk | W36: =HYPERLINK("https://drive.google.com/file/d/1R5oaXZE5pJqUYPhwmhyJlYt_kShIYPoC/view?usp=drivesdk","테스트_진로적성검사_2026") -> 테스트_진로적성검사_2026 | X36: Document successfully created; Document successfully merged; PDF created; Run via form trigger as jeongjinung4@gmail.com; Timestamp: Aug 13, 2026 8:22 PM | AA36: SENT | AB36: 46248.398
A37: 김지욱 | B37: 2025 | C37: INFJ | D37: rlawldnr2166@gmail.com | E37: 야전·실무형(R) | F37: 귀하의 진로적성검사 결과를 종합하면 야전·실무형(R) 성향이 두드러지며, 이는 장비 운용과 현장 중심의 임무 수행에서 강점을 보이는 전형적인 야전형 장교로 성장할 가능성을 의미합니다. 이러한 성향은 군 환경에서 전투장비 운용과 유지관리, 전술적 운용, 병력 통제 등 실제 전투력과 직결되는 분야에서 특히 중요한 역할을 하며, 전투장비를 운용하는 보병(기보)·포병·기갑·방공·육군항공과 같은 전투임무 위주 병과뿐 아니라 공병, 정보통신,화학 등 기술 기반 병과에서도 높은 적합성을 보입니다. 전투병과 특기 선택시는 작전, 군수, 획득분야가 가장 적합합니다. 또한 군수, 병기, 병참, 수송 분야에서도 장비 관리와 운용 능력을 효과적으로 발휘할 수 있습니다. 전문인력 분야로는 통신·공병 등 기술 전문 분야나 무기체계 획득 및 관리와 같은 획득 전문 영역, 장비 중심 연구개발 분야에서도 발전 가능성이 큽니다. 현실형 장교는 전투 및 훈련 상황에서 빠르고 정확한 판단과 실행력을 바탕으로 가시적인 성과를 창출하며, 부하들에게 신뢰를 주는 장점이 있습니다. 다만 단기적 실행에 집중하는 경향으로 인해 장기적 안목 형성과 체계적인 기획 능력, 세밀한 의사소통, 유연한 상황 대응 및 병사 개개인에 대한 심리적 관리 측면에서는 보완이 필요합니다. 따라서 리더형(E, 리더십)이나 행정관리형(C, 정확한 업무수행) 성향을 함께 강화한다면 더욱 높은 성과를 기대할 수 있습니다. | G37: 36 | H37: 36 | I37: 36 | J37: 36 | K37: 36 | L37: 36 | U37: 1B_cw2WKu-MEiNkA8ShIp0eeCEi51KSQx | V37: https://drive.google.com/file/d/1B_cw2WKu-MEiNkA8ShIp0eeCEi51KSQx/view?usp=drivesdk | W37: =HYPERLINK("https://drive.google.com/file/d/1B_cw2WKu-MEiNkA8ShIp0eeCEi51KSQx/view?usp=drivesdk","김지욱_진로적성검사_2026") -> 김지욱_진로적성검사_2026 | X37: Document successfully created; Document successfully merged; PDF created; Run via form trigger as jeongjinung4@gmail.com; Timestamp: Aug 13, 2026 8:41 PM | AA37: SENT | AB37: 46248.404
A38: 김지욱 | B38: 2025 | C38: INFJ | D38: rlawldnr2166@gmail.com | E38: 야전·실무형(R) | F38: 귀하의 진로적성검사 결과를 종합하면 야전·실무형(R) 성향이 두드러지며, 이는 장비 운용과 현장 중심의 임무 수행에서 강점을 보이는 전형적인 야전형 장교로 성장할 가능성을 의미합니다. 이러한 성향은 군 환경에서 전투장비 운용과 유지관리, 전술적 운용, 병력 통제 등 실제 전투력과 직결되는 분야에서 특히 중요한 역할을 하며, 전투장비를 운용하는 보병(기보)·포병·기갑·방공·육군항공과 같은 전투임무 위주 병과뿐 아니라 공병, 정보통신,화학 등 기술 기반 병과에서도 높은 적합성을 보입니다. 전투병과 특기 선택시는 작전, 군수, 획득분야가 가장 적합합니다. 또한 군수, 병기, 병참, 수송 분야에서도 장비 관리와 운용 능력을 효과적으로 발휘할 수 있습니다. 전문인력 분야로는 통신·공병 등 기술 전문 분야나 무기체계 획득 및 관리와 같은 획득 전문 영역, 장비 중심 연구개발 분야에서도 발전 가능성이 큽니다. 현실형 장교는 전투 및 훈련 상황에서 빠르고 정확한 판단과 실행력을 바탕으로 가시적인 성과를 창출하며, 부하들에게 신뢰를 주는 장점이 있습니다. 다만 단기적 실행에 집중하는 경향으로 인해 장기적 안목 형성과 체계적인 기획 능력, 세밀한 의사소통, 유연한 상황 대응 및 병사 개개인에 대한 심리적 관리 측면에서는 보완이 필요합니다. 따라서 리더형(E, 리더십)이나 행정관리형(C, 정확한 업무수행) 성향을 함께 강화한다면 더욱 높은 성과를 기대할 수 있습니다. | G38: 36 | H38: 36 | I38: 36 | J38: 36 | K38: 36 | L38: 36 | U38: 12gbaaOEkPRbbHt9CgGu6Sf2CE2L-YXDj | V38: https://drive.google.com/file/d/12gbaaOEkPRbbHt9CgGu6Sf2CE2L-YXDj/view?usp=drivesdk | W38: =HYPERLINK("https://drive.google.com/file/d/12gbaaOEkPRbbHt9CgGu6Sf2CE2L-YXDj/view?usp=drivesdk","김지욱_진로적성검사_2026") -> 김지욱_진로적성검사_2026 | X38: Document successfully created; Document successfully merged; PDF created; Run via form trigger as jeongjinung4@gmail.com; Timestamp: Aug 13, 2026 8:41 PM | AA38: SENT | AB38: 46248.404
A39: 양지현 | B39: 2022 | C39: ENTJ | D39: ary0423@gmail.com | E39: 리더형(E) | F39: 귀하의 검사 결과, 리더형(E) 성향이 강하게 나타났습니다. 리더십과 의사결정 능력(협의, 조정)이 뛰어나며, 조직을 이끌고 목표를 달성하는 데 강점을 가진 유형입니다. 또한 이 유형은 상황을 빠르게 파악하고 방향을 설정하여 조직을 이끄는 능력이 뛰어나며, 부하들을 동기부여하고 목표 달성을 위해 자원을 효과적으로 배분하는 데 능숙합니다. 군에서는 이러한 성향이 지휘관 역할과 직결됩니다. 귀하에게는 보병, 포병, 기갑 등 모든 전투 병과에서의 전투부대 지휘 역할에 적합하여 조직 관리 능력을 발휘할 수 있습니다. 전문인력 분야에서는 정책전문, 국제전문(무관 등), 획득전문(방위사업 관련) 분야가 적합합니다. 향후에는 단순한 리더십을 넘어 전문성과 현장 이해를 함께 갖추는 것이 중요합니다. 야전·실무형(R,현장감각)이나 관계형(S,대인관계) 성향을 보완한다면 더욱 균형 잡힌 지휘관으로 성장할 수 있습니다. 또한 전투병과 장교는 지휘관과 참모직위를 모두 이수해야 하므로 참모로서의 섬세함과 업무관리 능력을 함양해야 한다. | G39: 41 | H39: 53 | I39: 43 | J39: 56 | K39: 58 | L39: 56 | U39: 1G-T5pGyNLuYZRrpsIAB0lVdThmOQ5Pdz | V39: https://drive.google.com/file/d/1G-T5pGyNLuYZRrpsIAB0lVdThmOQ5Pdz/view?usp=drivesdk | W39: =HYPERLINK("https://drive.google.com/file/d/1G-T5pGyNLuYZRrpsIAB0lVdThmOQ5Pdz/view?usp=drivesdk","양지현_진로적성검사_2026") -> 양지현_진로적성검사_2026 | X39: Document successfully created; Document successfully merged; PDF created; Run via form trigger as jeongjinung4@gmail.com; Timestamp: Aug 13, 2026 8:41 PM | AA39: SENT | AB39: 46248.404
A40: 홍서희 | B40: 2025 | C40: ISTJ | D40: sally770312@gmail.com | E40: 행정·관리형(C) | F40: 귀하의 진로적성검사 결과, 행정·관리형(C) 성향이 중심적으로 나타났습니다. 체계적인 관리와 정확한 업무 수행에 강점을 가진 유형으로, 군 조직의 안정적 운영을 유지하는 데 필수적인 역할을 담당합니다. 귀하에게는 인사행정, 재정, 군수, 병참, 병기, 군사경찰, 법무 분야가 적합합니다. 전문인력 분야에서는 정책전문(행정 및 제도, 인력운영), 획득전문(방산 계약 및 관리), 기술전문(체계 운영), 특수전문(국방분석) 분야가 적합합니다. 향후에는 정확성과 함께 상황 대응 능력을 함께 강화하는 것이 중요합니다. 야전·실무형(R, 현장감각, 창의적 사고 및 표현) 또는 기술·분석형(I, 분석능력) 성향을 보완하면 보다 실무 중심의 경쟁력을 갖출 수 있습니다. 위에서 추천드린 기술병과, 행정병과(군사경찰)는 지휘관 직위를 필수로 이수해야 하므로 현장 감각을 유지하며 리더십 함양에도 힘써야 합니다. | G40: 32 | H40: 31 | I40: 32 | J40: 41 | K40: 40 | L40: 42 | U40: 1YRByEbm3uRjfKbOztBWKgz7ku_rCqmR3 | V40: https://drive.google.com/file/d/1YRByEbm3uRjfKbOztBWKgz7ku_rCqmR3/view?usp=drivesdk | W40: =HYPERLINK("https://drive.google.com/file/d/1YRByEbm3uRjfKbOztBWKgz7ku_rCqmR3/view?usp=drivesdk","홍서희_진로적성검사_2026") -> 홍서희_진로적성검사_2026 | X40: Document successfully created; Document successfully merged; PDF created; Run via form trigger as jeongjinung4@gmail.com; Timestamp: Aug 13, 2026 8:41 PM | AA40: SENT | AB40: 46248.404
...

Sheet 설문시트
A1: 타임스탬프 | B1: 본인은 위에 제시된 개인정보 제공사항에 동의하십니까? | C1: 이름(별칭도 가능) | D1: 임관년도(형식 : 0000) | E1: MBTI (대문자로 표시) | F1: 이메일 (army.mil 불가) | G1: 제목 없는 질문 [군 장비(차량, 화기, 장비)를 직접 다루고 정비하는 것이 좋다] | H1: 제목 없는 질문 [군 장비나 시스템의 작동 원리를 분석하는 것이 흥미롭다] | I1: 제목 없는 질문 [군 홍보물, 영상, 디자인 작업에 관심이 있다] | J1: 제목 없는 질문 [동료나 후임을 도와주는 것에서 보람을 느낀다] | K1: 제목 없는 질문 [팀이나 분대를 이끄는 역할을 맡고 싶다] | L1: 제목 없는 질문 [군 행정업무(문서, 보고서 작성)를 정확하게 수행할 수 있다] | M1: 제목 없는 질문 [총기 등의 장비를 분해하고 내부 구조를 이해하는 것을 좋아한다] | N1: 제목 없는 질문 [데이터를 기반으로 상황을 분석하고 결론을 도출하는 것을 좋아한다] | O1: 제목 없는 질문 [창의적인 방식의 임무수행을 좋아한다] | P1: 제목 없는 질문 [부대원을 교육하거나 지도하는 역할에 관심이 있다] | Q1: 제목 없는 질문 [중요한 결정을 내리는 위치에 서고 싶다] | R1: 제목 없는 질문 [군 규정과 절차를 철저히 지키는 것이 중요하다고 생각한다] | S1: 제목 없는 질문 [실내 근무보다 야외에서 임무를 수행하는 것을 선호한다] | T1: 제목 없는 질문 [문제를 논리적으로 해결하는 데 자신이 있다] | U1: 제목 없는 질문 [사진 촬영이나 영상 편집에 흥미가 있다] | V1: 제목 없는 질문 [부대원의 고민을 잘 들어주고 공감하는 편이다] | W1: 제목 없는 질문 [명확한 목표를 세우고 부대원을 이끄는 데 자신 있다] | X1: 제목 없는 질문 [물자와 보급품을 체계적으로 관리할 수 있다] | Y1: 제목 없는 질문 [공구를 사용하여 전투장비나 시설을 수리하는 데 거부감이 없다] | Z1: 제목 없는 질문 [새로운 기술(IT, 무기체계 등)을 배우는 것이 즐겁다] | AA1: 제목 없는 질문 [음악, 공연, 문화 활동에 참여하는 것을 즐긴다] | AB1: 제목 없는 질문 [부대 내 분위기를 좋게 만드는 데 기여하고 싶다] | AC1: 제목 없는 질문 [부대원을 설득하고 동기를 부여할 수 있다] | AD1: 제목 없는 질문 [기록 및 정리 업무를 꼼꼼하게 수행할 수 있다] | AE1: 제목 없는 질문 [통신 장비나 케이블을 설치·점검하는 작업을 할 수 있다] | AF1: 제목 없는 질문 [작전 상황을 분석하고 미래를 예측하는 역할에 관심 있다] | AG1: 제목 없는 질문 [기존 방식보다 새로운 아이디어를 제시하는 편이다] | AH1: 제목 없는 질문 [전우애를 중요하게 생각한다] | AI1: 제목 없는 질문 [위기 상황에서 책임지고 판단할 수 있다] | AJ1: 제목 없는 질문 [반복적인 업무도 꾸준히 수행할 수 있다] | AK1: 제목 없는 질문 [반복적인 전투장비 점검 및 유지보수 작업을 수행할 수 있다] | AL1: 제목 없는 질문 [복잡한 문제도 끝까지 파고들어 해결하려는 성향이 있다] | AM1: 제목 없는 질문 [디자인이나 콘텐츠 제작 활동을 좋아한다] | AN1: 제목 없는 질문 [갈등 상황에서 중재하는 역할을 맡을 수 있다] | AO1: 제목 없는 질문 [경쟁 상황에서 앞서고 싶은 욕구가 강하다] | AP1: 제목 없는 질문 [숫자나 장부 관리에 자신이 있다] | AQ1: 제목 없는 질문 [몸을 쓰는 훈련이나 작업이 많은 임무를 선호한다] | AR1: 제목 없는 질문 [전투 장비나 지휘통제 시스템 운용 업무에 흥미가 있다] | AS1: 제목 없는 질문 [감정이나 생각을 표현하는 활동에 거리낌이 없다] | AT1: 제목 없는 질문 [다른 사람의 성장이나 적응을 돕는 일에 관심 있다] | AU1: 제목 없는 질문 [군대 조직 내에서 영향력을 발휘하고 싶다] | AV1: 제목 없는 질문 [계획된 일정에 따라 움직이는 것을 선호한다] | AW1: 제목 없는 질문 [전투장비 고장 시 원인을 직접 찾아 해결하는 것이 흥미롭다] | AX1: 제목 없는 질문 [정보 수집 후 이를 체계적으로 정리하고 분석할 수 있다] | AY1: 제목 없는 질문 [군의 틀에 박힌 방식보다 자유로운 표현을 선호한다] | AZ1: 제목 없는 질문 [부대원과 협력하여 문제를 해결하는 것을 선호한다] | BA1: 제목 없는 질문 [부대원 앞에서 발표하거나 지시하는 것이 어렵지 않다] | BB1: 제목 없는 질문 [실수 없이 정확하게 일을 처리하는 것이 중요하다] | BC1: 제목 없는 질문 [위험 요소가 있는 부대 현장 작업에서도 침착하게 임무를 수행할 수 있다] | BD1: 제목 없는 질문 [훈련간 발생한 문제의 원인과 결과를 따져보는 사고방식을 자주 사용한다] | BE1: 제목 없는 질문 [시각적 요소(포스터, 영상 등)에 관심이 많다] | BF1: 제목 없는 질문 [부대원들과 소통하는 것이 어렵지 않다] | BG1: 제목 없는 질문 [임무 달성을 위해 적극적으로 행동하는 편이다] | BH1: 제목 없는 질문 [체계적인 부대 시스템 속에서 일하는 것이 편하다] | BI1: 제목 없는 질문 [매뉴얼에 따라 장비를 정확하게 다루는 것이 중요하다고 생각한다] | BJ1: 제목 없는 질문 [단순 반복 업무보다 문제 해결 중심의 업무를 선호한다] | BK1: 제목 없는 질문 [부대 내에서 창의적인 역할을 맡고 싶다] | BL1: 제목 없는 질문 [부대 내에서 배려와 지원 역할을 자연스럽게 맡는다] | BM1: 제목 없는 질문 [지휘자(관)로서 인정받는 것에 동기부여를 느낀다] | BN1: 제목 없는 질문 [정해진 양식과 기준에 맞춰 일을 수행하는 것을 선호한다] | BO1: 제목 없는 질문 [장비 운용 시 안전과 임무 효율 사이의 균형을 고려할 수 있다] | BP1: 제목 없는 질문 [기술적 오류나 이상 징후를 논리적으로 추적해 원인을 규명하려 한다] | BQ1: 제목 없는 질문 [복잡한 메시지를 간결하고 인상적으로 표현하려 한다] | BR1: 제목 없는 질문 [계급 차이가 있어도 구성원의 의견을 존중하며 소통하려 한다] | BS1: 제목 없는 질문 [실패의 책임을 회피하기보다 스스로 감당하려는 태도를 가진다] | BT1: 제목 없는 질문 [규정 준수가 안전한 임무수행과 직결된다고 인식한다] | BU1: 제목 없는 질문 [장비 손실이나 고장 상황에서도 대체 수단을 빠르게 찾는 편이다] | BV1: 제목 없는 질문 [불완전한 정보 속에서도 상황을 추론하고 판단 근거를 만들 수 있다] | BW1: 제목 없는 질문 [정형화된 보고 방식 외에도 상황에 맞는 표현 방식을 고민한다] | BX1: 제목 없는 질문 [스트레스 상황에 놓인 부대원의 심리 상태를 빠르게 파악하려 한다] | BY1: 제목 없는 질문 [제한된 시간 내 우선순위를 설정하고 조직을 움직일 수 있다] | BZ1: 제목 없는 질문 [작은 행정 오류도 전체 임무에 영향을 줄 수 있다고 생각한다]
A2: 46246.372 | B2: 동의합니다. | C2: 최종혁 | D2: 2025 | E2: Intp | F2: jonghyeokchoi77@gmail.com | G2: 5 | H2: 5 | I2: 5 | J2: 5 | K2: 5 | L2: 5 | M2: 5 | N2: 5 | O2: 5 | P2: 5 | Q2: 5 | R2: 5 | S2: 5 | T2: 5 | U2: 5 | V2: 5 | W2: 5 | X2: 5 | Y2: 5 | Z2: 5 | AA2: ERROR: Invalid Email Address | AB2: 5 | AC2: 5 | AD2: 5 | AE2: 5 | AF2: 5 | AG2: 5 | AH2: 5 | AI2: 5 | AJ2: 5 | AK2: 5 | AL2: 5 | AM2: 5 | AN2: 5 | AO2: 5 | AP2: 5 | AQ2: 5 | AR2: 5 | AS2: 5 | AT2: 5 | AU2: 5 | AV2: 5 | AW2: 5 | AX2: 5 | AY2: 5 | AZ2: 5 | BA2: 5 | BB2: 5 | BC2: 5 | BD2: 5 | BE2: 5 | BF2: 5 | BG2: 5 | BH2: 5 | BI2: 5 | BJ2: 5 | BK2: 5 | BL2: 5 | BM2: 5 | BN2: 5 | BO2: 5 | BP2: 5 | BQ2: 5 | BR2: 5 | BS2: 5 | BT2: 5 | BU2: 5 | BV2: 5 | BW2: 5 | BX2: 5 | BY2: 5 | BZ2: 5
A3: 46247.57 | B3: 동의합니다. | C3: 너ㅓㅁ | D3: 2020 | E3: HHIK | F3: jonghyeokchoi77@gmail.com | G3: 1 | H3: 2 | I3: 3 | J3: 4 | K3: 1 | L3: 2 | M3: 4 | N3: 2 | O3: 3 | P3: 3 | Q3: 3 | R3: 2 | S3: 4 | T3: 3 | U3: 3 | V3: 2 | W3: 2 | X3: 4 | Y3: 4 | Z3: 2 | AA3: 2 | AB3: 4 | AC3: 4 | AD3: 2 | AE3: 4 | AF3: 4 | AG3: 4 | AH3: 2 | AI3: 2 | AJ3: 3 | AK3: 3 | AL3: 2 | AM3: 3 | AN3: 3 | AO3: 3 | AP3: 2 | AQ3: 2 | AR3: 3 | AS3: 3 | AT3: 2 | AU3: 2 | AV3: 3 | AW3: 3 | AX3: 2 | AY3: 2 | AZ3: 3 | BA3: 3 | BB3: 2 | BC3: 3 | BD3: 3 | BE3: 2 | BF3: 3 | BG3: 3 | BH3: 2 | BI3: 3 | BJ3: 3 | BK3: 2 | BL3: 2 | BM3: 3 | BN3: 4 | BO3: 2 | BP3: 4 | BQ3: 2 | BR3: 2 | BS3: 2 | BT3: 4 | BU3: 2 | BV3: 4 | BW3: 2 | BX3: 4 | BY3: 2 | BZ3: 4
A4: 46247.58 | B4: 동의합니다. | C4: 김민석 | D4: 2023 | E4: ESTP | F4: sdijk2114@naver.com | G4: 3 | H4: 3 | I4: 1 | J4: 4 | K4: 4 | L4: 2 | M4: 3 | N4: 1 | O4: 4 | P4: 3 | Q4: 3 | R4: 3 | S4: 3 | T4: 3 | U4: 1 | V4: 3 | W4: 3 | X4: 1 | Y4: 2 | Z4: 3 | AA4: 1 | AB4: 2 | AC4: 3 | AD4: 3 | AE4: 1 | AF4: 3 | AG4: 2 | AH4: 3 | AI4: 4 | AJ4: 4 | AK4: 2 | AL4: 3 | AM4: 1 | AN4: 3 | AO4: 3 | AP4: 1 | AQ4: 3 | AR4: 2 | AS4: 2 | AT4: 2 | AU4: 3 | AV4: 3 | AW4: 1 | AX4: 3 | AY4: 2 | AZ4: 4 | BA4: 4 | BB4: 4 | BC4: 3 | BD4: 2 | BE4: 1 | BF4: 4 | BG4: 4 | BH4: 3 | BI4: 3 | BJ4: 2 | BK4: 2 | BL4: 3 | BM4: 4 | BN4: 3 | BO4: 2 | BP4: 1 | BQ4: 3 | BR4: 4 | BS4: 4 | BT4: 3 | BU4: 3 | BV4: 2 | BW4: 2 | BX4: 3 | BY4: 4 | BZ4: 4
A5: 46247.582 | B5: 동의합니다. | C5: Jejsj | D5: 2020 | E5: Ahah | F5: jonghyeokchoi77@gmail.com | G5: 1 | H5: 1 | I5: 4 | J5: 4 | K5: 4 | L5: 1 | M5: 2 | N5: 4 | O5: 4 | P5: 2 | Q5: 2 | R5: 4 | S5: 2 | T5: 2 | U5: 4 | V5: 4 | W5: 2 | X5: 2 | Y5: 4 | Z5: 2 | AA5: 2 | AB5: 4 | AC5: 4 | AD5: 2 | AE5: 2 | AF5: 4 | AG5: 4 | AH5: 2 | AI5: 2 | AJ5: 2 | AK5: 4 | AL5: 4 | AM5: 2 | AN5: 2 | AO5: 2 | AP5: 2 | AQ5: 4 | AR5: 2 | AS5: 2 | AT5: 2 | AU5: 4 | AV5: 2 | AW5: 2 | AX5: 4 | AY5: 4 | AZ5: 2 | BA5: 2 | BB5: 4 | BC5: 4 | BD5: 2 | BE5: 2 | BF5: 4 | BG5: 2 | BH5: 2 | BI5: 4 | BJ5: 4 | BK5: 2 | BL5: 2 | BM5: 4 | BN5: 4 | BO5: 2 | BP5: 2 | BQ5: 4 | BR5: 4 | BS5: 2 | BT5: 2 | BU5: 4 | BV5: 4 | BW5: 2 | BX5: 2 | BY5: 2 | BZ5: 2
A6: 46247.584 | B6: 동의합니다. | C6: 80 황우진 | D6: 2025 | E6: ENFJ | F6: a52154309@gmail.com | G6: 1 | H6: 1 | I6: 1 | J6: 1 | K6: 1 | L6: 1 | M6: 1 | N6: 1 | O6: 1 | P6: 1 | Q6: 1 | R6: 1 | S6: 1 | T6: 1 | U6: 1 | V6: 2 | W6: 1 | X6: 1 | Y6: 4 | Z6: 1 | AA6: 1 | AB6: 4 | AC6: 2 | AD6: 1 | AE6: 3 | AF6: 1 | AG6: 4 | AH6: 2 | AI6: 4 | AJ6: 2 | AK6: 4 | AL6: 2 | AM6: 4 | AN6: 2 | AO6: 3 | AP6: 2 | AQ6: 3 | AR6: 2 | AS6: 2 | AT6: 3 | AU6: 4 | AV6: 2 | AW6: 4 | AX6: 2 | AY6: 3 | AZ6: 3 | BA6: 3 | BB6: 2 | BC6: 3 | BD6: 2 | BE6: 3 | BF6: 2 | BG6: 3 | BH6: 3 | BI6: 2 | BJ6: 3 | BK6: 2 | BL6: 2 | BM6: 3 | BN6: 1 | BO6: 4 | BP6: 2 | BQ6: 2 | BR6: 3 | BS6: 2 | BT6: 3 | BU6: 2 | BV6: 3 | BW6: 2 | BX6: 3 | BY6: 2 | BZ6: 3
A7: 46247.598 | B7: 동의합니다. | C7: Bdhdh | D7: 2020 | E7: Jaja | F7: jonghyeokchoi77@gmail.com | G7: 1 | H7: 3 | I7: 1 | J7: 3 | K7: 4 | L7: 4 | M7: 1 | N7: 4 | O7: 4 | P7: 4 | Q7: 1 | R7: 1 | S7: 4 | T7: 4 | U7: 4 | V7: 1 | W7: 1 | X7: 4 | Y7: 4 | Z7: 4 | AA7: 1 | AB7: 1 | AC7: 4 | AD7: 4 | AE7: 4 | AF7: 1 | AG7: 1 | AH7: 4 | AI7: 4 | AJ7: 4 | AK7: 1 | AL7: 1 | AM7: 4 | AN7: 4 | AO7: 4 | AP7: 1 | AQ7: 1 | AR7: 4 | AS7: 4 | AT7: 4 | AU7: 1 | AV7: 1 | AW7: 4 | AX7: 4 | AY7: 4 | AZ7: 1 | BA7: 4 | BB7: 4 | BC7: 4 | BD7: 1 | BE7: 4 | BF7: 4 | BG7: 4 | BH7: 1 | BI7: 1 | BJ7: 4 | BK7: 1 | BL7: 2 | BM7: 2 | BN7: 3 | BO7: 3 | BP7: 2 | BQ7: 2 | BR7: 3 | BS7: 3 | BT7: 2 | BU7: 2 | BV7: 3 | BW7: 3 | BX7: 2 | BY7: 3 | BZ7: 3
A8: 46247.602 | B8: 동의합니다. | C8: Shej | D8: 2020 | E8: Shhs | F8: jonghyeokchoi77@gmail.com | G8: 1 | H8: 3 | I8: 3 | J8: 2 | K8: 2 | L8: 4 | M8: 4 | N8: 2 | O8: 4 | P8: 4 | Q8: 2 | R8: 4 | S8: 4 | T8: 2 | U8: 4 | V8: 4 | W8: 2 | X8: 3 | Y8: 3 | Z8: 2 | AA8: 3 | AB8: 3 | AC8: 2 | AD8: 3 | AE8: 3 | AF8: 2 | AG8: 3 | AH8: 3 | AI8: 2 | AJ8: 4 | AK8: 4 | AL8: 2 | AM8: 4 | AN8: 4 | AO8: 4 | AP8: 2 | AQ8: 4 | AR8: 2 | AS8: 4 | AT8: 2 | AU8: 4 | AV8: 2 | AW8: 4 | AX8: 4 | AY8: 2 | AZ8: 4 | BA8: 2 | BB8: 4 | BC8: 2 | BD8: 4 | BE8: 2 | BF8: 4 | BG8: 4 | BH8: 2 | BI8: 4 | BJ8: 2 | BK8: 3 | BL8: 2 | BM8: 3 | BN8: 2 | BO8: 3 | BP8: 2 | BQ8: 2 | BR8: 3 | BS8: 2 | BT8: 4 | BU8: 2 | BV8: 4 | BW8: 2 | BX8: 4 | BY8: 2 | BZ8: 4
A9: 46247.604 | B9: 동의합니다. | C9: Llll | D9: 2020 | E9: Jaja | F9: jonghyeokchoi77@gmail.com | G9: 1 | H9: 1 | I9: 4 | J9: 4 | K9: 4 | L9: 1 | M9: 1 | N9: 4 | O9: 4 | P9: 1 | Q9: 1 | R9: 4 | S9: 4 | T9: 1 | U9: 1 | V9: 4 | W9: 4 | X9: 4 | Y9: 1 | Z9: 4 | AA9: 4 | AB9: 4 | AC9: 1 | AD9: 1 | AE9: 4 | AF9: 4 | AG9: 1 | AH9: 1 | AI9: 2 | AJ9: 2 | AK9: 2 | AL9: 2 | AM9: 3 | AN9: 3 | AO9: 3 | AP9: 2 | AQ9: 2 | AR9: 3 | AS9: 3 | AT9: 2 | AU9: 2 | AV9: 3 | AW9: 3 | AX9: 2 | AY9: 3 | AZ9: 3 | BA9: 2 | BB9: 2 | BC9: 3 | BD9: 3 | BE9: 2 | BF9: 3 | BG9: 3 | BH9: 3 | BI9: 2 | BJ9: 3 | BK9: 3 | BL9: 3 | BM9: 2 | BN9: 2 | BO9: 3 | BP9: 3 | BQ9: 2 | BR9: 3 | BS9: 2 | BT9: 3 | BU9: 2 | BV9: 2 | BW9: 3 | BX9: 2 | BY9: 3 | BZ9: 3
A10: 46247.615 | B10: 동의합니다. | C10: 테스트 | D10: 1 | E10: 1 | F10: enrud1103@naver.com | G10: 5 | H10: 5 | I10: 5 | J10: 5 | K10: 5 | L10: 5 | M10: 5 | N10: 5 | O10: 5 | P10: 5 | Q10: 5 | R10: 5 | S10: 5 | T10: 5 | U10: 5 | V10: 5 | W10: 5 | X10: 5 | Y10: 5 | Z10: 5 | AA10: 5 | AB10: 5 | AC10: 5 | AD10: 5 | AE10: 5 | AF10: 5 | AG10: 5 | AH10: 5 | AI10: 5 | AJ10: 5 | AK10: 5 | AL10: 5 | AM10: 5 | AN10: 5 | AO10: 5 | AP10: 5 | AQ10: 5 | AR10: 5 | AS10: 5 | AT10: 5 | AU10: 5 | AV10: 5 | AW10: 5 | AX10: 5 | AY10: 5 | AZ10: 5 | BA10: 5 | BB10: 5 | BC10: 5 | BD10: 5 | BE10: 5 | BF10: 5 | BG10: 5 | BH10: 5 | BI10: 5 | BJ10: 5 | BK10: 5 | BL10: 5 | BM10: 5 | BN10: 5 | BO10: 5 | BP10: 5 | BQ10: 5 | BR10: 5 | BS10: 5 | BT10: 5 | BU10: 5 | BV10: 5 | BW10: 5 | BX10: 5 | BY10: 5 | BZ10: 5
